Workbook

Sheet Branch Batch Plan
A1: One City Developers Ltd.
A2: Land Sales Office
A3: Commercial Cove, House: 56/C, Road: 132, Gulshan-1, Dhaka-1212.
A7: SL. | B7: Team: | C7: Name: | D7: Designation: | E7: Emp. ID | F7: Joining Date: | G7: Office Contact:
A8: 01 | B8: Branch Individual | C8: Abu Sufian Shohag | D8: GM (Br. In Charge) | E8: 6179 | F8: 45791 | G8: 01905596105
A9: 02 | C9: Touhidul Islam | D9: Sr. AGM | E9: 6247 | F9: 45931 | G9: 01905-536326
A10: 03 | C10: Md. Safiqul Islam | D10: Manager | E10: 2882 | F10: 45787 | G10: 01894-944616
A11: 04 | C11: Md. Manir Sikder | D11: Sr. Dep. Manager | E11: 6181 | F11: 45792 | G11: 01905596178
A12: 05 | C12: Md. Yeasin Rasel | D12: Sr. Executive | E12: 6282 | F12: 45997 | G12: 01905596329
A13: Batch Leader | C13: Nurul Islam Ripon | D13: GM | E13: 20241 | F13: 45945 | G13: 01990-786628
A14: 01 | B14: Batch-01 | C14: Most. Liza Akter | D14: Sr. Dep. Manager | E14: 6215 | F14: 45871 | G14: 01905596106
A15: 02 | C15: Jakir Ahammed Noor | D15: Dep. Manager | E15: 6287 | F15: 46023 | G15: 01905596328
A16: 03 | C16: Anowar Hossain | D16: Asst. Manager | E16: 6176 | F16: 45787 | G16: 01905596172
A17: 04 | C17: Abrarul Haque Emon | D17: Asst. Manager | E17: 2922 | F17: 45823 | G17: 01905596181
A18: Batch Leader | C18: Masud Shahriar | D18: AGM | E18: 0065 | F18: 43822 | G18: 01880-089005
A19: 01 | B19: Batch-02 | C19: Omar Sharif Arman | D19: Sr. Manager | E19: 0206 | F19: 44251 | G19: 01880-089017
A20: 02 | C20: Mst. Sharmin Akter Nabila | D20: Asst. Manager | E20: 20039 | F20: 45854 | G20: 01880-089006
A21: 03 | C21: Maria Akter Mim | D21: Executive | E21: 6195 | F21: 45857 | G21: 01335-144074
A22: 04 | C22: Afroza Yeasmin Rumi | D22: Asst. Manager | E22: 20164 | F22: 45910 | G22: 01896-006156
A23: 05 | C23: Md. Jahid Hasan | D23: Sr. Executive | E23: 6260 | F23: 45972 | G23: 01905596184
C30: Admin | D30: Branch In Charge | G30: DMD

Sheet Current Manpower
A1: One City Developers Ltd.
A2: Land Sales Office
A3: Commercial Cove, House: 56/C, Road: 132, Gulshan-1, Dhaka-1212.
C4: TODAY
C5: =TODAY() -> 46291
A6: SL. | B6: Team: | C6: Name: | D6: Designation: | E6: Emp. ID | F6: Office Contact: | G6: Personal Cont: | H6: DOJ | I6: Duration | J6: Last Sale Date | K6: Zero Sale Duration | L6: DOB | M6: Blood Group | N6: Present Address | O6: Permanent Address | P6: Remarks
A7: 01 | B7: Br. In Charge | C7: Abu Sufian Shohag | D7: Senior DGM | E7: 6179 | F7: 01905596105 | G7: 01867-054038 | H7: 45791 | I7: =DATEDIF(H7,$C$5,"y")&"y-"&DATEDIF(H7,$C$5,"ym")&"m-"&DATEDIF(H7,$C$5,"md")&"d" -> 1y-4m-12d | J7: 45971 | K7: =DATEDIF(J7,$C$5,"y")&"y-"&DATEDIF(J7,$C$5,"ym")&"m-"&DATEDIF(J7,$C$5,"md")&"d" -> 0y-10m-16d | L7: 29312
A8: 02 | C8: Nurul Islam Ripon | D8: GM | E8: 20241 | F8: 01990-786628 | H8: 45945 | I8: =DATEDIF(H8,'Total Manpower'!$B$5,"y")&"y-"&DATEDIF(H8,'Total Manpower'!$B$5,"ym")&"m-"&DATEDIF(H8,'Total Manpower'!$B$5,"md")&"d" -> 0y-11m-11d | L8: 29632 | N8: R-08, House-24, Banasree, Rampura, Dhaka-1219.
A9: 03 | B9: Batch-01 | C9: Most. Liza Akter | D9: Dep. Manager | E9: 6215 | F9: 01905596106 | H9: 45871 | I9: =DATEDIF(H9,$C$5,"y")&"y-"&DATEDIF(H9,$C$5,"ym")&"m-"&DATEDIF(H9,$C$5,"md")&"d" -> 1y-1m-24d | J9: 45997 | K9: 126y-4m-2d
A10: 04 | C10: Jakir Ahammed Noor | D10: Dep. Manager | E10: 6287 | F10: 01905596328 | G10: 01757-112810 | H10: 46023 | I10: =DATEDIF(H10,$C$5,"y")&"y-"&DATEDIF(H10,$C$5,"ym")&"m-"&DATEDIF(H10,$C$5,"md")&"d" -> 0y-8m-25d | K10: 126y-4m-2d | L10: 29587 | M10: AB+ (VE) | N10: House-234,vRoad -01, Chandudsan, Mohammadpur, Dhaka | O10: Vill: Professor para, Po,Ps,Dist: Joypurhat
A11: 05 | C11: Md. Shahinul Islam | D11: Asst. Manager | E11: 6259 | F11: 01905596103 | G11: 01625-465633 | H11: 45972 | I11: =DATEDIF(H11,$C$5,"y")&"y-"&DATEDIF(H11,$C$5,"ym")&"m-"&DATEDIF(H11,$C$5,"md")&"d" -> 0y-10m-15d | J11: 46000 | K11: 0y-4m-23d | L11: 35948 | M11: O+ (VE) | N11: House: J-05, Road: 05, Nayan Biriyani, Middle Badda, Gulshan, Dhaka | O11: Bepari Bari, Rudragaon, Faridganj, Chandpur.
A12: 06 | C12: Farjana Tanjila | D12: Sr. Executive | E12: 6332 | F12: 01905-596108 | G12: 01777-923184 | H12: 46204 | I12: =DATEDIF(H12,'Total Manpower'!$B$5,"y")&"y-"&DATEDIF(H12,'Total Manpower'!$B$5,"ym")&"m-"&DATEDIF(H12,'Total Manpower'!$B$5,"md")&"d" -> 0y-2m-25d | L12: 34299 | M12: B+ (Ve) | N12: 46, Road:01, Block: A, Niketon, Gulshan, Dhaka | O12: 730, Kanchon, Rupgonj, Narayongonj | S12: =DATEDIF(P7,$G$5,"Y")&"years,"&DATEDIF(P7,$G$5,"ym")&"months,"&DATEDIF(P7,$G$5,"md")&"days" -> 0years,0months,0days
A13: 07 | C13: Anowar Hossain | D13: Executive | E13: 6176 | F13: 01905596172 | H13: 45787 | I13: =DATEDIF(H13,$C$5,"y")&"y-"&DATEDIF(H13,$C$5,"ym")&"m-"&DATEDIF(H13,$C$5,"md")&"d" -> 1y-4m-16d | J13: 45977 | K13: 0y-5m-16d | L13: 36428
A14: 08 | C14: Abrarul Haque Emon | D14: Executive | E14: 2922 | F14: 01905596181 | G14: 01618-123083 | H14: 45823 | I14: =DATEDIF(H14,$C$5,"y")&"y-"&DATEDIF(H14,$C$5,"ym")&"m-"&DATEDIF(H14,$C$5,"md")&"d" -> 1y-3m-11d | K14: 126y-4m-2d | L14: 36601
A15: 09 | B15: Batch-02 | C15: Masud Shahriar | D15: Sr. Manager | E15: 0065 | F15: 01880-089005 | H15: 43822 | I15: =DATEDIF(H15,$C$5,"y")&"y-"&DATEDIF(H15,$C$5,"ym")&"m-"&DATEDIF(H15,$C$5,"md")&"d" -> 6y-9m-3d
A16: 10 | C16: Md. Estiak Mahbub | D16: Sr. Executive | E16: 6299 | F16: 01401-216526 | G16: 01317-212242 | H16: 46032 | I16: =DATEDIF(H16,$C$5,"y")&"y-"&DATEDIF(H16,$C$5,"ym")&"m-"&DATEDIF(H16,$C$5,"md")&"d" -> 0y-8m-16d | K16: 126y-4m-2d | L16: 38650 | M16: O+ (VE) | N16: 56/A, West Rajabazar, Tejgaon, Dhaka | O16: Norosinghopu, Najirganj, Sujanagar, Pabna.
A17: 11 | C17: Mst. Sharmin Akter Nabila | D17: Sr. Executive | E17: 20039 | F17: 01880-089006 | H17: 45854 | I17: =DATEDIF(H17,'Total Manpower'!$B$5,"y")&"y-"&DATEDIF(H17,'Total Manpower'!$B$5,"ym")&"m-"&DATEDIF(H17,'Total Manpower'!$B$5,"md")&"d" -> 1y-2m-10d | L17: 36916 | M17: A+ (VE) | N17: Alfun Garden, Gulshan-2 | O17: Udaypur, Barishal
A18: 12 | C18: Afroza Yeasmin Rumi | D18: Executive | E18: 20164 | F18: 01896-006156 | H18: 45910 | I18: =DATEDIF(H18,'Total Manpower'!$B$5,"y")&"y-"&DATEDIF(H18,'Total Manpower'!$B$5,"ym")&"m-"&DATEDIF(H18,'Total Manpower'!$B$5,"md")&"d" -> 1y-0m-16d | L18: 35619
A19: 13 | C19: Maria Akter Mim | D19: Executive | E19: 6195 | F19: 01335-144074 | G19: 01307-477907 | H19: 45857 | I19: =DATEDIF(H19,'Total Manpower'!$B$5,"y")&"y-"&DATEDIF(H19,'Total Manpower'!$B$5,"ym")&"m-"&DATEDIF(H19,'Total Manpower'!$B$5,"md")&"d" -> 1y-2m-7d | L19: 38353 | M19: B+ (Ve) | N19: Shish Kababer Goli, South badda, Gulshan, Dhaka | O19: West Charamaddi, Charamaddi, Bakergonj, Barishal
A20: 14 | C20: Md. Jahid Hasan | D20: Executive | E20: 6260 | F20: 01905596184 | H20: 45972 | I20: =DATEDIF(H20,$C$5,"y")&"y-"&DATEDIF(H20,$C$5,"ym")&"m-"&DATEDIF(H20,$C$5,"md")&"d" -> 0y-10m-15d
A21: 15 | B21: Batch-03 | C21: Touhidul Islam | D21: Sr. AGM | E21: 6247 | F21: 01905-536326 | G21: 01714-014951 | H21: 45931 | I21: =DATEDIF(H21,'Total Manpower'!$B$5,"y")&"y-"&DATEDIF(H21,'Total Manpower'!$B$5,"ym")&"m-"&DATEDIF(H21,'Total Manpower'!$B$5,"md")&"d" -> 0y-11m-25d | L21: 27942 | M21: B+ (VeO | N21: H-10 (6th Floor), R-15, B-G/1, Section-2, Mirpur, Dhaka1216. | O21: Banchha Nagar, Lakshmipur, Sadar, Lakshmipur
A22: 16 | C22: Omar Sharif Arman | D22: Manager | E22: 0206 | F22: 01880-089017 | H22: 44251 | I22: =DATEDIF(H22,$C$5,"y")&"y-"&DATEDIF(H22,$C$5,"ym")&"m-"&DATEDIF(H22,$C$5,"md")&"d" -> 5y-7m-2d | K22: 126y-4m-2d
A23: 17 | C23: Md. Safiqul Islam | D23: Manager | E23: 2882 | F23: 01894-944616 | H23: 45787 | I23: =DATEDIF(H23,$C$5,"y")&"y-"&DATEDIF(H23,$C$5,"ym")&"m-"&DATEDIF(H23,$C$5,"md")&"d" -> 1y-4m-16d
A24: 18 | C24: Md. Manir Sikder | D24: Dep. Manager | E24: 6181 | F24: 01905596178 | H24: 45792 | I24: =DATEDIF(H24,$C$5,"y")&"y-"&DATEDIF(H24,$C$5,"ym")&"m-"&DATEDIF(H24,$C$5,"md")&"d" -> 1y-4m-11d | K24: 126y-4m-2d | L24: 33946
A25: 19 | C25: Md. Yeasin Rasel | D25: Executive | E25: 6282 | F25: 01905596329 | G25: 01865-996050 | H25: 45997 | I25: =DATEDIF(H25,$C$5,"y")&"y-"&DATEDIF(H25,$C$5,"ym")&"m-"&DATEDIF(H25,$C$5,"md")&"d" -> 0y-9m-20d | K25: 126y-4m-2d
A26: 20 | C26: Hafiza Khanam | D26: Sr. Executive | E26: 6329 | F26: 01905-596331 | G26: 01632-581664 | H26: 46152 | I26: =DATEDIF(H26,'Total Manpower'!$B$5,"y")&"y-"&DATEDIF(H26,'Total Manpower'!$B$5,"ym")&"m-"&DATEDIF(H26,'Total Manpower'!$B$5,"md")&"d" -> 0y-4m-16d | L26: 33984 | M26: A+ (VE) | N26: 1469, Chowdhury Monjil, South Donia, Dhaka-1236 | O26: Borobari, Changariya, Guthiya, Uzirpur, Barishal-8200
A27: 21 | B27: Others Dep. | C27: Nasiruddin Chowdury | D27: Deputy Manager | E27: 9172 | F27: 01905596176 | G27: 01818-101902 | H27: 45783 | I27: =DATEDIF(H27,$C$5,"y")&"y-"&DATEDIF(H27,$C$5,"ym")&"m-"&DATEDIF(H27,$C$5,"md")&"d" -> 1y-4m-20d | L27: 35531 | M27: O+ (VE)
A28: 22 | C28: Md. Salahuddin | D28: Asst. Manager | E28: 6291 | F28: 01905596186 | G28: 01825-344949 | H28: 46023 | I28: =DATEDIF(H28,$C$5,"y")&"y-"&DATEDIF(H28,$C$5,"ym")&"m-"&DATEDIF(H28,$C$5,"md")&"d" -> 0y-8m-25d | K28: =DATEDIF(J28,$B$5,"y")&"y-"&DATEDIF(J28,$B$5,"ym")&"m-"&DATEDIF(J28,$B$5,"md")&"d" -> 0y-0m-0d | L28: 33090 | M28: B+ (Ve) | N28: 23/C, Jhigatola, Flate: 9/D, Hazaribag, Dhaka-1209 | O28: Soroshpu, pohordanga, Noragati, Narail
A29: 23 | C29: Samia Akter | D29: Front Desk | E29: 6246 | F29: 01905596104 | G29: 01705-357257 | H29: 45934 | I29: =DATEDIF(H29,$C$5,"y")&"y-"&DATEDIF(H29,$C$5,"ym")&"m-"&DATEDIF(H29,$C$5,"md")&"d" -> 0y-11m-22d | L29: 38480 | M29: A+ (VE) | N29: Adarsha Chayanir, Ring Road, Shompa Market, Mohammadpur. | O29: Goshar hat, Muladi, Khuner Char, Hizla, Barishal
A30: 24 | C30: Md Harunur Rashid | D30: Executive | F30: 01324-933977 | G30: 01854-390982 | H30: 46033 | I30: =DATEDIF(H30,$C$5,"y")&"y-"&DATEDIF(H30,$C$5,"ym")&"m-"&DATEDIF(H30,$C$5,"md")&"d" -> 0y-8m-15d | M30: O+ (VE) | N30: Asim Goli, South Badda, Dhaka | O30: Maowlana A. Rajjak Saheber Bari, Purbo Mirza Nagar, Nateshwar, Sonaimuri, Noakhali
A31: 25 | C31: Md. Sadek Mia | D31: Supervisor | E31: 7102 | G31: 01617-314786 | H31: 45783 | I31: =DATEDIF(H31,$C$5,"y")&"y-"&DATEDIF(H31,$C$5,"ym")&"m-"&DATEDIF(H31,$C$5,"md")&"d" -> 1y-4m-20d | L31: 36330
A32: 26
A33: 28 | C33: Abdullah Biswas | D33: Off. Assistant | E33: 7106 | G33: 01812-151691 | H33: 45773 | I33: =DATEDIF(H33,$C$5,"y")&"y-"&DATEDIF(H33,$C$5,"ym")&"m-"&DATEDIF(H33,$C$5,"md")&"d" -> 1y-5m-0d | L33: 39066
C34: Md. Ibrahim | D34: Driver | E34: 7170 | G34: 01328-169826 | H34: 44992 | I34: =DATEDIF(H34,$C$5,"y")&"y-"&DATEDIF(H34,$C$5,"ym")&"m-"&DATEDIF(H34,$C$5,"md")&"d" -> 3y-6m-19d
C35: Md. Anower Hossain (Sohel) | D35: Driver | F35: 01772195677 | H35: 46204 | I35: =DATEDIF(H35,$C$5,"y")&"y-"&DATEDIF(H35,$C$5,"ym")&"m-"&DATEDIF(H35,$C$5,"md")&"d" -> 0y-2m-25d
A36: 29 | C36: Md. Soyab | D36: Driver | G36: 01780339916 | H36: 46258 | I36: =DATEDIF(H36,$C$5,"y")&"y-"&DATEDIF(H36,$C$5,"ym")&"m-"&DATEDIF(H36,$C$5,"md")&"d" -> 0y-1m-2d | L36: 32234 | M36: A+ (VE) | N36: Address: House: Pandit Bari, Village: Raichand, Post Office: Raichand 8332, Lalmohan, Place of Birth BHOLA | O36: Address: House: Pandit Bari, Village: Raichand, Post Office: Raichand 8332, Lalmohan, Place of Birth BHOLA

Sheet Mobile Recharge Sheet
B1: One City Developers Ltd.
B2: Land Sales Office
B3: Commercial Cove, House: 56/C, Road: 132, Gulshan-1, Dhaka-1212.
B7: Date:06-September-2026
B8: SL. | C8: Dep. | D8: Name | E8: Designation | F8: Office Contact | G8: Amount | H8: Signature
B9: 01 | C9: CRM | D9: Abu Sufian Shohag | E9: GM | F9: 01905596105 | G9: 650
B10: 02 | D10: Nurul Islam Ripon | E10: GM | F10: 01990-786628 | G10: 650
B11: 03 | D11: Touhidul Islam | E11: Sr. AGM | F11: 01905-536326 | G11: 650
B12: 04 | D12: Masud Shahriar | E12: AGM | F12: 01880-089005 | G12: 650
B13: 05 | D13: Omar Sharif Arman | E13: Sr. Manager | F13: 01880-089017 | G13: 650
B14: 06 | D14: Md. Safiqul Islam | E14: Manager | F14: 01894-944616 | G14: 650
B15: 07 | D15: Md. Manir Sikder | E15: Sr. Dep. Magr | F15: 01905596178 | G15: 650
B16: 08 | D16: Most. Liza Akter | E16: Sr. Dep. Magr | F16: 01905596106 | G16: 650
B17: 09 | D17: Jakir Ahammed Noor | E17: Dep. Manager | F17: 01905596328 | G17: 650
B18: 10 | D18: Mst. Sharmin Akter Nabila | E18: Asst. Manager | F18: 01880-089006 | G18: 650
B19: 11 | D19: Afroza Yeasmin Rumi | E19: Asst. Manager | F19: 01896-006156 | G19: 650
B20: 12 | D20: Anowar Hossain | E20: Asst. Manager | F20: 01905596172 | G20: 650
B21: 13 | D21: Abrarul Haque Emon | E21: Asst. Manager | F21: 01905596181 | G21: 650
... B24: 16 | D24: Maria Akter Mim | E24: Executive | F24: 01335-144074 | G24: 650
B25: 17 | C25: Others Dep. | D25: Nasiruddin Chowdury | E25: Manager | F25: 01818-101902 | G25: 650
B26: 18 | D26: Md. Salahuddin | E26: Asst. Manager | F26: 01905596186 | G26: 409
B27: 19 | D27: Samia Akter | E27: Sr. Executive | F27: 01905596104 | G27: 409
B28: Total= | G28: =SUM(G9:G27) -> 11868
D35: Admin | E35: Accounts | G35: Branch In Charge

Sheet Total Manpower
A1: One City Developers Ltd.
A2: Land Sales Office
A3: Commercial Cove, House: 56/C, Road: 132, Gulshan-1, Dhaka-1212.
B4: TODAY
B5: =TODAY() -> 46291
A6: SL. | B6: Name: | C6: Designation: | D6: Emp. ID | E6: Office Contact: | F6: Personal Cont: | G6: DOJ | H6: Duration | I6: Last Sale Date | J6: Zero Sale Duration | K6: DOB | L6: Blood Group | M6: Present Address | N6: Permanent Address | O6: Remarks
A7: 01 | B7: Abu Sufian Shohag | C7: Senior DGM | D7: 6179 | E7: 01905596105 | F7: 01867-054038 | G7: 45791 | H7: =DATEDIF(G7,$B$5,"y")&"y-"&DATEDIF(G7,$B$5,"ym")&"m-"&DATEDIF(G7,$B$5,"md")&"d" -> 1y-4m-12d | I7: 45971 | J7: =DATEDIF(I7,$B$5,"y")&"y-"&DATEDIF(I7,$B$5,"ym")&"m-"&DATEDIF(I7,$B$5,"md")&"d" -> 0y-10m-16d | K7: 29312
A8: 02 | B8: Bashir Ahmed | C8: Sr. Manager | D8: 6182 | E8: 01905596179 | F8: 01865-345544 | G8: 45792 | H8: =DATEDIF(G8,$B$5,"y")&"y-"&DATEDIF(G8,$B$5,"ym")&"m-"&DATEDIF(G8,$B$5,"md")&"d" -> 1y-4m-11d | I8: 45987 | J8: =DATEDIF(I8,$B$5,"y")&"y-"&DATEDIF(I8,$B$5,"ym")&"m-"&DATEDIF(I8,$B$5,"md")&"d" -> 0y-10m-0d | K8: 33887 | L8: B+ (Ve) | M8: Shapla Housing, Vanga Bridge, 60 Ft. Agargaon. | N8: Bhuiyan Bari, Khoishar, Daudpur, Rupganj, Narayangonj.
A9: 03 | B9: Sharowar Hossain | C9: Dep. Manager | D9: 6214 | E9: 01905596175 | G9: 45871 | H9: =DATEDIF(G9,$B$5,"y")&"y-"&DATEDIF(G9,$B$5,"ym")&"m-"&DATEDIF(G9,$B$5,"md")&"d" -> 1y-1m-24d | I9: 45955 | J9: =DATEDIF(I9,$B$5,"y")&"y-"&DATEDIF(I9,$B$5,"ym")&"m-"&DATEDIF(I9,$B$5,"md")&"d" -> 0y-11m-1d | R9: =DATEDIF(O7,$F$5,"Y")&"years,"&DATEDIF(O7,$F$5,"ym")&"months,"&DATEDIF(O7,$F$5,"md")&"days" -> 0years,0months,0days
A10: 04 | B10: Most. Liza Akter | C10: Sr. Executive | D10: 6215 | E10: 01905596106 | G10: 45871 | H10: =DATEDIF(G10,$B$5,"y")&"y-"&DATEDIF(G10,$B$5,"ym")&"m-"&DATEDIF(G10,$B$5,"md")&"d" -> 1y-1m-24d | I10: 45997 | J10: =DATEDIF(I10,$B$5,"y")&"y-"&DATEDIF(I10,$B$5,"ym")&"m-"&DATEDIF(I10,$B$5,"md")&"d" -> 0y-9m-20d
A11: 05 | B11: Md. Shahinul Islam | C11: Asst. Manager | D11: 6259 | E11: 01905596103 | F11: 01625-465633 | G11: 45972 | H11: =DATEDIF(G11,$B$5,"y")&"y-"&DATEDIF(G11,$B$5,"ym")&"m-"&DATEDIF(G11,$B$5,"md")&"d" -> 0y-10m-15d | I11: 46000 | J11: =DATEDIF(I11,$B$5,"y")&"y-"&DATEDIF(I11,$B$5,"ym")&"m-"&DATEDIF(I11,$B$5,"md")&"d" -> 0y-9m-17d | K11: 35948 | L11: O+ (VE) | M11: House: J-05, Road: 05, Nayan Biriyani, Middle Badda, Gulshan, Dhaka | N11: Bepari Bari, Rudragaon, Faridganj, Chandpur.
A12: 06 | B12: Md. Mehedi Hasan | C12: Sr. Executive | D12: 6213 | E12: 01905596108 | F12: 01410-400494 | G12: 45879 | H12: =DATEDIF(G12,$B$5,"y")&"y-"&DATEDIF(G12,$B$5,"ym")&"m-"&DATEDIF(G12,$B$5,"md")&"d" -> 1y-1m-16d | J12: =DATEDIF(I12,$B$5,"y")&"y-"&DATEDIF(I12,$B$5,"ym")&"m-"&DATEDIF(I12,$B$5,"md")&"d" -> 126y-8m-27d | K12: 34427
A13: 07 | B13: H M Owaliullah Farhad | C13: Sr. Executive | E13: 01905596118 | G13: 45901 | H13: =DATEDIF(G13,$B$5,"y")&"y-"&DATEDIF(G13,$B$5,"ym")&"m-"&DATEDIF(G13,$B$5,"md")&"d" -> 1y-0m-25d | J13: =DATEDIF(I13,$B$5,"y")&"y-"&DATEDIF(I13,$B$5,"ym")&"m-"&DATEDIF(I13,$B$5,"md")&"d" -> 126y-8m-27d
A14: 08 | B14: Amiya Islam Shamrin | C14: Sr. Executive | E14: 01905596117 | G14: 45901 | H14: =DATEDIF(G14,$B$5,"y")&"y-"&DATEDIF(G14,$B$5,"ym")&"m-"&DATEDIF(G14,$B$5,"md")&"d" -> 1y-0m-25d | J14: =DATEDIF(I14,$B$5,"y")&"y-"&DATEDIF(I14,$B$5,"ym")&"m-"&DATEDIF(I14,$B$5,"md")&"d" -> 126y-8m-27d | K14: 34017
A15: 09 | B15: Agnes Modhu Nodi | C15: Sr. Executive | D15: 6262 | E15: 01905596332 | G15: 45973 | H15: =DATEDIF(G15,$B$5,"y")&"y-"&DATEDIF(G15,$B$5,"ym")&"m-"&DATEDIF(G15,$B$5,"md")&"d" -> 0y-10m-14d | J15: =DATEDIF(I15,$B$5,"y")&"y-"&DATEDIF(I15,$B$5,"ym")&"m-"&DATEDIF(I15,$B$5,"md")&"d" -> 126y-8m-27d
A16: 10 | B16: Anowar Hossain | C16: Executive | D16: 6176 | E16: 01905596172 | G16: 45787 | H16: =DATEDIF(G16,$B$5,"y")&"y-"&DATEDIF(G16,$B$5,"ym")&"m-"&DATEDIF(G16,$B$5,"md")&"d" -> 1y-4m-16d | I16: 45977 | J16: =DATEDIF(I16,$B$5,"y")&"y-"&DATEDIF(I16,$B$5,"ym")&"m-"&DATEDIF(I16,$B$5,"md")&"d" -> 0y-10m-10d | K16: 36428
A17: 11 | B17: Abrarul Haque Emon | C17: Executive | D17: 2922 | E17: 01905596181 | F17: 01618-123083 | G17: 45823 | H17: =DATEDIF(G17,$B$5,"y")&"y-"&DATEDIF(G17,$B$5,"ym")&"m-"&DATEDIF(G17,$B$5,"md")&"d" -> 1y-3m-11d | J17: =DATEDIF(I17,$B$5,"y")&"y-"&DATEDIF(I17,$B$5,"ym")&"m-"&DATEDIF(I17,$B$5,"md")&"d" -> 126y-8m-27d | K17: 36601
A18: 12 | B18: Md Atiful Haque | C18: Executive | D18: 6238 | E18: 01905596331 | F18: 01755-204537 | G18: 45901 | H18: =DATEDIF(G18,$B$5,"y")&"y-"&DATEDIF(G18,$B$5,"ym")&"m-"&DATEDIF(G18,$B$5,"md")&"d" -> 1y-0m-25d | J18: =DATEDIF(I18,$B$5,"y")&"y-"&DATEDIF(I18,$B$5,"ym")&"m-"&DATEDIF(I18,$B$5,"md")&"d" -> 126y-8m-27d | K18: 38026 | L18: AB+ (Ve) | M18: House: 03, Road, 07, Sector: 10, Uttara, Dhaka | N18: Rajar Vita, Romna, Chilmari, Kurigram
A19: 13 | B19: Mst. Umme Afja Limu | C19: Executive | D19: 6203 | E19: 01905596328 | G19: 45859 | H19: =DATEDIF(G19,$B$5,"y")&"y-"&DATEDIF(G19,$B$5,"ym")&"m-"&DATEDIF(G19,$B$5,"md")&"d" -> 1y-2m-5d | J19: =DATEDIF(I19,$B$5,"y")&"y-"&DATEDIF(I19,$B$5,"ym")&"m-"&DATEDIF(I19,$B$5,"md")&"d" -> 126y-8m-27d | K19: 35795
A20: 14 | B20: Surma Akter | C20: Executive | D20: 9182 | E20: 01905596109 | F20: 01768-293280 | G20: 45879 | H20: =DATEDIF(G20,$B$5,"y")&"y-"&DATEDIF(G20,$B$5,"ym")&"m-"&DATEDIF(G20,$B$5,"md")&"d" -> 1y-1m-16d | J20: =DATEDIF(I20,$B$5,"y")&"y-"&DATEDIF(I20,$B$5,"ym")&"m-"&DATEDIF(I20,$B$5,"md")&"d" -> 126y-8m-27d | K20: 35170
A21: 15 | B21: Md. Siam Ashrafi Sumon | C21: Executive | D21: 6257 | E21: 01905596180 | G21: 45971 | H21: =DATEDIF(G21,$B$5,"y")&"y-"&DATEDIF(G21,$B$5,"ym")&"m-"&DATEDIF(G21,$B$5,"md")&"d" -> 0y-10m-16d | J21: =DATEDIF(I21,$B$5,"y")&"y-"&DATEDIF(I21,$B$5,"ym")&"m-"&DATEDIF(I21,$B$5,"md")&"d" -> 126y-8m-27d
A22: 16 | B22: Md. Yeasin Rasel | C22: Executive | D22: 6282 | E22: 01905596329 | F22: 01865-996050 | G22: 45997 | H22: =DATEDIF(G22,$B$5,"y")&"y-"&DATEDIF(G22,$B$5,"ym")&"m-"&DATEDIF(G22,$B$5,"md")&"d" -> 0y-9m-20d | J22: =DATEDIF(I22,$B$5,"y")&"y-"&DATEDIF(I22,$B$5,"ym")&"m-"&DATEDIF(I22,$B$5,"md")&"d" -> 126y-8m-27d
A23: 17 | B23: Israt Jahan | C23: Executive | F23: 01753-030795 | G23: 46009 | H23: 0y-0m-6d | I23: 46009 | J23: 0y-0m-6d | K23: 45932 | L23: B+ (Ve) | M23: 1097, West Nondipara, Khilgaon, Dhaka | N23: Paik Para, Abdullahpur, Munshiganj.
A24: 18 | B24: Kazi Mizanur Rahman | C24: Manager | D24: 6289 | F24: 01716-591435 | G24: 46023 | H24: =DATEDIF(G24,$B$5,"y")&"y-"&DATEDIF(G24,$B$5,"ym")&"m-"&DATEDIF(G24,$B$5,"md")&"d" -> 0y-8m-25d | J24: =DATEDIF(I24,$B$5,"y")&"y-"&DATEDIF(I24,$B$5,"ym")&"m-"&DATEDIF(I24,$B$5,"md")&"d" -> 126y-8m-27d | K24: 26665 | L24: A+ (Ve) | M24: House: 590, Road:08, Avenue: 4, DOHS, Mirpur, Dhaka | N24: Kazi Monjil, Plice Line Road, Kumarkhali, Sadar, Pirpjpur.
A25: 19 | B25: Md. Abdul Kaium Sohag | C25: DGM | D25: 6171 | E25: 01905596165 | G25: 45704 | H25: =DATEDIF(G25,$B$5,"y")&"y-"&DATEDIF(G25,$B$5,"ym")&"m-"&DATEDIF(G25,$B$5,"md")&"d" -> 1y-7m-10d | J25: =DATEDIF(I25,$B$5,"y")&"y-"&DATEDIF(I25,$B$5,"ym")&"m-"&DATEDIF(I25,$B$5,"md")&"d" -> 126y-8m-27d | K25: 32813
A26: 20 | B26: Md. Manir Sikder | C26: Dep. Manager | D26: 6181 | E26: 01905596178 | G26: 45792 | H26: =DATEDIF(G26,$B$5,"y")&"y-"&DATEDIF(G26,$B$5,"ym")&"m-"&DATEDIF(G26,$B$5,"md")&"d" -> 1y-4m-11d | J26: =DATEDIF(I26,$B$5,"y")&"y-"&DATEDIF(I26,$B$5,"ym")&"m-"&DATEDIF(I26,$B$5,"md")&"d" -> 126y-8m-27d | K26: 33946
A27: 21 | B27: Md. Ridoy Khan | C27: Asst. Manager | D27: 6174 | E27: 01905596168 | G27: 45710 | H27: =DATEDIF(G27,$B$5,"y")&"y-"&DATEDIF(G27,$B$5,"ym")&"m-"&DATEDIF(G27,$B$5,"md")&"d" -> 1y-7m-4d | I27: 45872 | J27: =DATEDIF(I27,$B$5,"y")&"y-"&DATEDIF(I27,$B$5,"ym")&"m-"&DATEDIF(I27,$B$5,"md")&"d" -> 1y-1m-23d | K27: 34837
A28: 22 | B28: Akhi Akter Urmi | C28: Sr. Executive | D28: 6234 | E28: 01905596173 | G28: 45890 | H28: =DATEDIF(G28,$B$5,"y")&"y-"&DATEDIF(G28,$B$5,"ym")&"m-"&DATEDIF(G28,$B$5,"md")&"d" -> 1y-1m-5d | J28: =DATEDIF(I28,$B$5,"y")&"y-"&DATEDIF(I28,$B$5,"ym")&"m-"&DATEDIF(I28,$B$5,"md")&"d" -> 126y-8m-27d
A29: 23 | B29: Labonno Shikder | C29: Sr. Executive | D29: 6228 | E29: 01905596330 | G29: 45886 | H29: =DATEDIF(G29,$B$5,"y")&"y-"&DATEDIF(G29,$B$5,"ym")&"m-"&DATEDIF(G29,$B$5,"md")&"d" -> 1y-1m-9d | J29: =DATEDIF(I29,$B$5,"y")&"y-"&DATEDIF(I29,$B$5,"ym")&"m-"&DATEDIF(I29,$B$5,"md")&"d" -> 126y-8m-27d | K29: 35364
A30: 24 | B30: Md. Jahir Rayhan | C30: Sr. Executive | D30: 6232 | E30: 01905596110 | G30: 45889 | H30: =DATEDIF(G30,$B$5,"y")&"y-"&DATEDIF(G30,$B$5,"ym")&"m-"&DATEDIF(G30,$B$5,"md")&"d" -> 1y-1m-6d | J30: =DATEDIF(I30,$B$5,"y")&"y-"&DATEDIF(I30,$B$5,"ym")&"m-"&DATEDIF(I30,$B$5,"md")&"d" -> 126y-8m-27d | K30: 36029
A31: 25 | B31: Nurunnahar Popy | C31: Sr. Executive | D31: 6244 | E31: 01905596241 | G31: 45916 | H31: =DATEDIF(G31,$B$5,"y")&"y-"&DATEDIF(G31,$B$5,"ym")&"m-"&DATEDIF(G31,$B$5,"md")&"d" -> 1y-0m-10d | J31: =DATEDIF(I31,$B$5,"y")&"y-"&DATEDIF(I31,$B$5,"ym")&"m-"&DATEDIF(I31,$B$5,"md")&"d" -> 126y-8m-27d | K31: 37391
A32: 26 | B32: Md. Altahid Hossain Ashik | C32: Sr. Executive | D32: 6222 | E32: 01905596107 | F32: 01629-985484 | G32: 45871 | H32: =DATEDIF(G32,$B$5,"y")&"y-"&DATEDIF(G32,$B$5,"ym")&"m-"&DATEDIF(G32,$B$5,"md")&"d" -> 1y-1m-24d | J32: =DATEDIF(I32,$B$5,"y")&"y-"&DATEDIF(I32,$B$5,"ym")&"m-"&DATEDIF(I32,$B$5,"md")&"d" -> 126y-8m-27d | K32: 35389
A33: 27 | B33: Ananna Ahmed | C33: Executive | D33: 6194 | E33: 01905596182 | F33: 01777-987725 | G33: 45840 | H33: =DATEDIF(G33,$B$5,"y")&"y-"&DATEDIF(G33,$B$5,"ym")&"m-"&DATEDIF(G33,$B$5,"md")&"d" -> 1y-2m-24d | I33: 45840 | J33: =DATEDIF(I33,$B$5,"y")&"y-"&DATEDIF(I33,$B$5,"ym")&"m-"&DATEDIF(I33,$B$5,"md")&"d" -> 1y-2m-24d | K33: 36047
A34: 28 | B34: Md. Noman Islam | C34: Executive | D34: 6202 | E34: 01905596327 | G34: 45859 | H34: =DATEDIF(G34,$B$5,"y")&"y-"&DATEDIF(G34,$B$5,"ym")&"m-"&DATEDIF(G34,$B$5,"md")&"d" -> 1y-2m-5d | J34: =DATEDIF(I34,$B$5,"y")&"y-"&DATEDIF(I34,$B$5,"ym")&"m-"&DATEDIF(I34,$B$5,"md")&"d" -> 126y-8m-27d | K34: 36281
A35: 29 | B35: Sourav Kundu | C35: Executive | D35: 6252 | E35: 01905596119 | G35: 45943 | H35: =DATEDIF(G35,$B$5,"y")&"y-"&DATEDIF(G35,$B$5,"ym")&"m-"&DATEDIF(G35,$B$5,"md")&"d" -> 0y-11m-13d | J35: =DATEDIF(I35,$B$5,"y")&"y-"&DATEDIF(I35,$B$5,"ym")&"m-"&DATEDIF(I35,$B$5,"md")&"d" -> 126y-8m-27d
A36: 30 | B36: Rabiul Islam | C36: Executive | D36: 6256 | E36: 01905596183 | G36: 45971 | H36: =DATEDIF(G36,$B$5,"y")&"y-"&DATEDIF(G36,$B$5,"ym")&"m-"&DATEDIF(G36,$B$5,"md")&"d" -> 0y-10m-16d | J36: =DATEDIF(I36,$B$5,"y")&"y-"&DATEDIF(I36,$B$5,"ym")&"m-"&DATEDIF(I36,$B$5,"md")&"d" -> 126y-8m-27d
A37: 31 | B37: Md. Jahid Hasan | C37: Executive | D37: 6260 | E37: 01905596184 | G37: 45972 | H37: =DATEDIF(G37,$B$5,"y")&"y-"&DATEDIF(G37,$B$5,"ym")&"m-"&DATEDIF(G37,$B$5,"md")&"d" -> 0y-10m-15d | J37: =DATEDIF(I37,$B$5,"y")&"y-"&DATEDIF(I37,$B$5,"ym")&"m-"&DATEDIF(I37,$B$5,"md")&"d" -> 126y-8m-27d
A38: 32 | B38: Kamrul Hasan | C38: Executive | F38: 01846-023212 | G38: 46001 | H38: =DATEDIF(G38,$B$5,"y")&"y-"&DATEDIF(G38,$B$5,"ym")&"m-"&DATEDIF(G38,$B$5,"md")&"d" -> 0y-9m-16d | K38: 35773 | L38: O+ (VE) | M38: Aftabnagar, Rampura, Dhaka. | N38: Gofran Mohajon Bari, Sonapur, Sadar Noakhali
A39: 33 | B39: Mehedi Hasan Pritom | C39: Executive | D39: 6263 | G39: 45973 | H39: =DATEDIF(G39,$B$5,"y")&"y-"&DATEDIF(G39,$B$5,"ym")&"m-"&DATEDIF(G39,$B$5,"md")&"d" -> 0y-10m-14d | J39: =DATEDIF(I39,$B$5,"y")&"y-"&DATEDIF(I39,$B$5,"ym")&"m-"&DATEDIF(I39,$B$5,"md")&"d" -> 126y-8m-27d
A40: 34 | B40: Joy Chandra De | C40: Executive | E40: 01905596118 | F40: 01619-929903 | G40: 46011 | H40: =DATEDIF(G40,$B$5,"y")&"y-"&DATEDIF(G40,$B$5,"ym")&"m-"&DATEDIF(G40,$B$5,"md")&"d" -> 0y-9m-6d | J40: =DATEDIF(I40,$B$5,"y")&"y-"&DATEDIF(I40,$B$5,"ym")&"m-"&DATEDIF(I40,$B$5,"md")&"d" -> 126y-8m-27d | K40: 36504 | L40: B+ (Ve) | M40: House: 230, Road: 04, Block: F, Bashundhara R/A, Dhaka | N40: House: 117, Ward: 03, Bhola Sadar, Bhola
...

Sheet 6 Month Eid Bonus
B1: One City Developers Ltd.
B2: Land Sales Office
B3: Commercial Cove, House: 56/C, Road: 132, Gulshan-1, Dhaka-1212.
B5: Date: 19/03/2026
B6: SL. | C6: Team: | D6: Name: | E6: Designation: | F6: Taka | G6: Signature
B7: 1 | D7: Sharowar Hossain | E7: Dep. Manager
B8: 2 | D8: Most. Liza Akter | E8: Dep. Manager
B9: 3 | D9: Md. Mehedi Hasan | E9: Sr. Executive
B10: 4 | D10: Akhi Akter Urmi | E10: Sr. Executive
B11: 5 | D11: Anowar Hossain | E11: Executive
B12: 6 | D12: Abrarul Haque Emon | E12: Executive
B13: 7 | D13: Md. Noman Islam | E13: Executive
B14: 8 | D14: Md. Manir Sikder | E14: Dep. Manager
B15: 9 | D15: Labonno Shikder | E15: Sr. Executive
B16: 10 | D16: Md. Altahid Hossain Ashik | E16: Sr. Executive
B17: 11 | D17: Ananna Ahmed | E17: Executive
B18: 12 | D18: Samir Al Hossain | E18: Asst. Manager
... B21: 15 | D21: Farzana Akter Purnima | E21: Executive
B22: Total= | F22: =SUM(F7:F21) -> 0

Sheet Others Attendance Bonus
B1: One City Developers Ltd.
B2: Land Sales Office
B3: Commercial Cove, House: 56/C, Road: 132, Gulshan-1, Dhaka-1212.
E6: Date: | F6: 46126
B7: SL. | C7: Name: | D7: Designation: | E7: Taka | F7: Signature
B8: 1 | C8: Nasiruddin Chowdury | D8: Admin & Acc. | E8: 1500
B9: 2 | C9: Md. Sadek Mia | D9: Supervisor | E9: 1000
B10: 3 | C10: Md Jashim Uddin (Ripon) | D10: Off. Assistant | E10: 1000
B11: 4 | C11: Abdullah Biswas | D11: Off. Assistant | E11: 1000
B12: 5 | C12: Md. Ibrahim | D12: Driver | E12: 1000
B13: Total= | E13: =SUM(E8:E12) -> 5500
C40: Admin | D40: Accounts | F40: Branch In Charge

Sheet Attendance Bonus
B1: One City Developers Ltd.
B2: Land Sales Office
B3: Commercial Cove, House: 56/C, Road: 132, Gulshan-1, Dhaka-1212.
B5: Date: 26/02/2026
B6: SL. | C6: Team: | D6: Name: | E6: Designation: | F6: Taka | G6: Signature
B7: 1 | C7: Team: A | D7: Abu Sufian Shohag | E7: Senior DGM | F7: 5000
B8: 2 | D8: Abdullah Al Mamun | E8: Sr. AGM | F8: 3000
B9: 3 | D9: Omar Sharif Arman | E9: Manager | F9: 2000
B10: 4 | D10: Most. Liza Akter | E10: Dep. Manager | F10: 3000
B11: 5 | D11: Jakir Ahammed Noor | E11: Dep. Manager | F11: 2000
B12: 6 | D12: Md. Shahinul Islam | E12: Asst. Manager | F12: 3000
B13: 7 | D13: Md. Mehedi Hasan | E13: Sr. Executive | F13: 1500
B14: 8 | D14: Anowar Hossain | E14: Executive | F14: 1000
B15: 9 | D15: Abrarul Haque Emon | E15: Executive | F15: 1500
B16: 10 | C16: Team: B | D16: Md. Parvez Kamal | E16: Manager | F16: 5000
B17: 11 | D17: Samir Al Hossain | E17: Asst. Manager | F17: 1500
B18: 12 | D18: Md Fahad Hasan Oney | E18: Sr. Executive | F18: 1500
B19: 13 | D19: Sourav Kundu | E19: Executive | F19: 1500
B20: 14 | D20: Md. Jahid Hasan | E20: Executive | F20: 1500
B21: 15 | D21: Md. Yeasin Rasel | E21: Executive | F21: 1500
B22: 16 | D22: Md. Omar Faruk Mridul | E22: Executive | F22: 1500
B23: 17 | D23: Minhaz Mohammed Ratul | E23: Executive | F23: 1500
B24: 18 | D24: Akbar Hossain Bhuiyan | E24: Executive | F24: 1500
B25: 19 | C25: Others Dep. | D25: Nasiruddin Chowdury | E25: Admin & Accounts | F25: 3000
B26: 20 | D26: Ranzan Kumar Dash | E26: Executive | F26: 1500
B27: 21 | D27: Md. Sadek Mia | E27: Supervisor | F27: 1500
B28: 22 | D28: Md Jashim Uddin (Ripon) | E28: Off. Assistant | F28: 1500
B29: 23 | D29: Abdullah Biswas | E29: Off. Assistant | F29: 1500
B30: 24 | D30: Md. Ibrahim | E30: Driver | F30: 1000
B31: Total= | F31: =SUM(F7:F30) -> 49000

Sheet Iftar List
B1: One City Developers Ltd.
B2: Land Sales Office
B3: Commercial Cove, House: 56/C, Road: 132, Gulshan-1, Dhaka-1212.
B5: Date:
B6: SL. | C6: Team: | D6: Name: | E6: Designation: | F6: Office Contact: | G6: Signature
B7: 1 | C7: Team: A | D7: Abu Sufian Shohag | E7: Senior DGM | F7: 01905596105
B8: 2 | D8: Md. Abdullah Al Mamun | E8: Sr. AGM | F8: 01905596179
B9: 3 | D9: Kazi Mizanur Rahman | E9: Manager | F9: 01905596110
B10: 4 | D10: Omar Sharif Arman | E10: Manager | F10: 01880-089017
B11: 5 | D11: Md. Abu Sayam Bhuiyan | E11: Manager | F11: 01905596165
B12: 6 | D12: Sharowar Hossain | E12: Dep. Manager | F12: 01905596175
B13: 7 | D13: Most. Liza Akter | E13: Dep. Manager | F13: 01905596106
B14: 8 | D14: Jakir Ahammed Noor | E14: Dep. Manager | F14: 01905596328
B15: 9 | D15: Md. Ridoy Khan | E15: Asst. Manager | F15: 01905596168
B16: 10 | D16: Md. Shahinul Islam | E16: Asst. Manager | F16: 01905596103
B17: 11 | D17: Md. Mehedi Hasan | E17: Sr. Executive | F17: 01905596108
B18: 12 | D18: Akhi Akter Urmi | E18: Sr. Executive | F18: 01905596173
B19: 13 | D19: Debosree Shaha Chowdhury | E19: Sr. Executive | F19: 01905596309
... B26: 20 | D26: Joy Chandra Dey | E26: Executive | F26: 01905-596118
B27: 21 | C27: Team: B | D27: Md. Parvez Kamal | E27: Manager | F27: 01880-089026
B28: 22 | D28: Md. Safiqul Islam | E28: Manager | F28: 01894-944616
B29: 23 | D29: Md. Manir Sikder | E29: Dep. Manager | F29: 01905-596178
B30: 24 | D30: Md. Salahuddin | E30: Asst. Manager | F30: 01905-596186
B31: 25 | D31: Mehedi Hasan Tahsan | E31: Asst. Manager | F31: 01905-596185
B32: 26 | D32: Samir Al Hossain | E32: Asst. Manager | F32: 01401-216512
B33: 27 | D33: Labonno Shikder | E33: Sr. Executive | F33: 01905596330
B34: 28 | D34: Md. Altahid Hossain Ashik | E34: Sr. Executive | F34: 01905596107
B35: 29 | D35: Md Fahad Hasan Oney | E35: Sr. Executive | F35: 01905596148
B36: 30 | D36: Jannatul Ferdaus | E36: Sr. Executive | F36: 01894-944623
B37: 31 | D37: Ananna Ahmed | E37: Executive | F37: 01905596182
B38: 32 | D38: Sourav Kundu | E38: Executive | F38: 01905596119
B39: 33 | D39: Rabiul Islam | E39: Executive | F39: 01905596183
... B46: 40 | D46: Farzana Akter Purnima | E46: Executive | F46: 01905-596344
B47: 41 | C47: Others Dep. | D47: Nasiruddin Chowdury | E47: Admin & Accounts | F47: 01905596176
B48: 42 | D48: Shahinul Islam Shahin | E48: Accounts | F48: 01905596167
B49: 43 | D49: Samia Akter | E49: Front Desk | F49: 01905596104
B50: 44 | D50: Md. Sadek Mia | E50: Supervisor
B51: 45 | D51: Md Jashim Uddin (Ripon) | E51: Off. Assistant
B52: 46 | D52: Abdullah Biswas | E52: Off. Assistant
B53: 47 | D53: Md. Ibrahim | E53: Driver
...

Sheet Sheet1
