Workbook

Sheet Daily KPI Entry Oct26
A2: Date | B2: Employee | C2: Batch | D2: Branch | E2: Collection Achv. | F2: Collection Point | G2: Int. Meeting Achv. | H2: Int. Meeting Point | I2: Ext. Meeting Achv | J2: Ext. Meeting Point | K2: Talk Time | L2: Client Reach/ Follow-up Achv. | M2: Client Reach/ Follow-up Point | N2: Appointment Achv. | O2: Appointment Point | P2: Dig. Marketing Point | Q2: Att. & Discipline Point | R2: KPI Mark Target | S2: Total KPI Points | T2: KPI Achievement % | U2: Gap | V2: Status | W2: Remarks
A3: 46296 | B3: Most. Liza Akter | C3: Batch-1 | D3: OCDL SO | E3: 0 | F3: =IF(E3>0,3,0) -> 0 | G3: 0 | H3: =IF(G3>0,1,0) -> 0 | I3: 1 | J3: =IF(I3>0,1,0) -> 1 | K3: 121 | L3: 52 | M3: =MIN(L3/50,1) -> 1 | N3: 3 | O3: =SUM(N3/3)*2 -> 2 | P3: 1 | Q3: 1 | R3: 10 | S3: =SUM(F3,H3,J3,M3,O3,P3,Q3) -> 6 | T3: =IFERROR(S3/10,0) -> 0.6 | U3: =S3-10 -> -4 | V3: =IF(T3>=1,"Achieved",IF(T3>=0.7,"Near Target",IF(T3>=0.5,"Average","Low Performance"))) -> Average
A4: 46296 | B4: Jakir Ahammed Noor | C4: Batch-1 | D4: OCDL SO | E4: 650000 | F4: =IF(E4>0,3,0) -> 3 | G4: 1 | H4: =IF(G4>0,1,0) -> 1 | I4: 2 | J4: =IF(I4>0,1,0) -> 1 | K4: 66 | L4: 51 | M4: =MIN(L4/50,1) -> 1 | N4: 3 | O4: =SUM(N4/3)*2 -> 2 | P4: 1 | Q4: 1 | R4: 10 | S4: =SUM(F4,H4,J4,M4,O4,P4,Q4) -> 10 | T4: =IFERROR(S4/10,0) -> 1 | U4: =S4-10 -> 0 | V4: =IF(T4>=1,"Achieved",IF(T4>=0.7,"Near Target",IF(T4>=0.5,"Average","Low Performance"))) -> Achieved
A5: 46296 | B5: Anowar Hossain | C5: Batch-1 | D5: OCDL SO | E5: 0 | F5: =IF(E5>0,3,0) -> 0 | G5: 0 | H5: =IF(G5>0,1,0) -> 0 | I5: 1 | J5: 1 | K5: 66 | L5: 52 | M5: =MIN(L5/50,1) -> 1 | N5: 3 | O5: =SUM(N5/3)*2 -> 2 | P5: 1 | Q5: 1 | R5: 10 | S5: =SUM(F5,H5,J5,M5,O5,P5,Q5) -> 6 | T5: =IFERROR(S5/10,0) -> 0.6 | U5: =S5-10 -> -4 | V5: =IF(T5>=1,"Achieved",IF(T5>=0.7,"Near Target",IF(T5>=0.5,"Average","Low Performance"))) -> Average
A6: 46296 | B6: Abrarul Haque Emon | C6: Batch-1 | D6: OCDL SO | E6: 300000 | F6: =IF(E6>0,3,0) -> 3 | G6: 1 | H6: =IF(G6>0,1,0) -> 1 | I6: 1 | J6: 1 | K6: 85 | L6: 50 | M6: =MIN(L6/50,1) -> 1 | N6: 3 | O6: =SUM(N6/3)*2 -> 2 | P6: 1 | Q6: 1 | R6: 10 | S6: =SUM(F6,H6,J6,M6,O6,P6,Q6) -> 10 | T6: =IFERROR(S6/10,0) -> 1 | U6: =S6-10 -> 0 | V6: =IF(T6>=1,"Achieved",IF(T6>=0.7,"Near Target",IF(T6>=0.5,"Average","Low Performance"))) -> Achieved
A7: 46296 | B7: Mst Sharmin Akter Nabila | C7: Batch-2 | D7: OCDL SO | E7: 0 | F7: =IF(E7>0,3,0) -> 0 | G7: 1 | H7: =IF(G7>0,1,0) -> 1 | I7: 0 | J7: 0 | K7: 80 | L7: 67 | M7: =MIN(L7/50,1) -> 1 | N7: 3 | O7: =SUM(N7/3)*2 -> 2 | P7: 1 | Q7: 1 | R7: 10 | S7: =SUM(F7,H7,J7,M7,O7,P7,Q7) -> 6 | T7: =IFERROR(S7/10,0) -> 0.6 | U7: =S7-10 -> -4 | V7: =IF(T7>=1,"Achieved",IF(T7>=0.7,"Near Target",IF(T7>=0.5,"Average","Low Performance"))) -> Average
A8: 46296 | B8: Afroza Yeasmin Rumi | C8: Batch-2 | D8: OCDL SO | E8: 0 | F8: =IF(E8>0,3,0) -> 0 | G8: 0 | H8: =IF(G8>0,1,0) -> 0 | I8: 1 | J8: =IF(I8>0,1,0) -> 1 | K8: 75 | L8: 53 | M8: =MIN(L8/50,1) -> 1 | N8: 3 | O8: =SUM(N8/3)*2 -> 2 | P8: 1 | Q8: 1 | R8: 10 | S8: =SUM(F8,H8,J8,M8,O8,P8,Q8) -> 6 | T8: =IFERROR(S8/10,0) -> 0.6 | U8: =S8-10 -> -4 | V8: =IF(T8>=1,"Achieved",IF(T8>=0.7,"Near Target",IF(T8>=0.5,"Average","Low Performance"))) -> Average
A9: 46296 | B9: Maria Akter Mim | C9: Batch-2 | D9: OCDL SO | E9: 0 | F9: =IF(E9>0,3,0) -> 0 | G9: 0 | H9: =IF(G9>0,1,0) -> 0 | I9: 1 | J9: 1 | K9: 64 | L9: 50 | M9: =MIN(L9/50,1) -> 1 | N9: 3 | O9: =SUM(N9/3)*2 -> 2 | P9: 1 | Q9: 1 | R9: 10 | S9: =SUM(F9,H9,J9,M9,O9,P9,Q9) -> 6 | T9: =IFERROR(S9/10,0) -> 0.6 | U9: =S9-10 -> -4 | V9: =IF(T9>=1,"Achieved",IF(T9>=0.7,"Near Target",IF(T9>=0.5,"Average","Low Performance"))) -> Average
A10: 46296 | B10: Jahid Hasan E | C10: Batch-2 | D10: OCDL SO | E10: 0 | F10: =IF(E10>0,3,0) -> 0 | G10: 0 | H10: =IF(G10>0,1,0) -> 0 | I10: 1 | J10: =IF(I10>0,1,0) -> 1 | K10: 65 | L10: 50 | M10: =MIN(L10/50,1) -> 1 | N10: 3 | O10: =SUM(N10/3)*2 -> 2 | P10: 1 | Q10: 1 | R10: 10 | S10: =SUM(F10,H10,J10,M10,O10,P10,Q10) -> 6 | T10: =IFERROR(S10/10,0) -> 0.6 | U10: =S10-10 -> -4 | V10: =IF(T10>=1,"Achieved",IF(T10>=0.7,"Near Target",IF(T10>=0.5,"Average","Low Performance"))) -> Average
A11: 46296 | B11: Safiqul Islam | C11: Batch-Ind | D11: OCDL SO | E11: 0 | F11: =IF(E11>0,3,0) -> 0 | G11: 0 | H11: =IF(G11>0,1,0) -> 0 | I11: 2 | J11: =IF(I11>0,1,0) -> 1 | K11: 75 | L11: 55 | M11: =MIN(L11/50,1) -> 1 | N11: 3 | O11: =SUM(N11/3)*2 -> 2 | P11: 1 | Q11: 1 | R11: 10 | S11: =SUM(F11,H11,J11,M11,O11,P11,Q11) -> 6 | T11: =IFERROR(S11/10,0) -> 0.6 | U11: =S11-10 -> -4 | V11: =IF(T11>=1,"Achieved",IF(T11>=0.7,"Near Target",IF(T11>=0.5,"Average","Low Performance"))) -> Average
A12: 46296 | B12: Manir Sikder | C12: Batch-Ind | D12: OCDL SO | E12: 0 | F12: =IF(E12>0,3,0) -> 0 | G12: 0 | H12: =IF(G12>0,1,0) -> 0 | I12: 2 | J12: =IF(I12>0,1,0) -> 1 | K12: 60 | L12: 50 | M12: =MIN(L12/50,1) -> 1 | N12: 3 | O12: =SUM(N12/3)*2 -> 2 | P12: 1 | Q12: 1 | R12: 10 | S12: =SUM(F12,H12,J12,M12,O12,P12,Q12) -> 6 | T12: =IFERROR(S12/10,0) -> 0.6 | U12: =S12-10 -> -4 | V12: =IF(T12>=1,"Achieved",IF(T12>=0.7,"Near Target",IF(T12>=0.5,"Average","Low Performance"))) -> Average
A13: 46296 | B13: Yeasin Rasel | C13: Batch-Ind | D13: OCDL SO | E13: 400000 | F13: =IF(E13>0,3,0) -> 3 | G13: 1 | H13: =IF(G13>0,1,0) -> 1 | I13: 1 | J13: =IF(I13>0,1,0) -> 1 | K13: 46 | L13: 50 | M13: =MIN(L13/50,1) -> 1 | N13: 3 | O13: =SUM(N13/3)*2 -> 2 | P13: 1 | Q13: 1 | R13: 10 | S13: =SUM(F13,H13,J13,M13,O13,P13,Q13) -> 10 | T13: =IFERROR(S13/10,0) -> 1 | U13: =S13-10 -> 0 | V13: =IF(T13>=1,"Achieved",IF(T13>=0.7,"Near Target",IF(T13>=0.5,"Average","Low Performance"))) -> Achieved
A14: 46298 | B14: Most. Liza Akter | C14: Batch-1 | D14: OCDL SO | E14: 0 | F14: =IF(E14>0,3,0) -> 0 | G14: 0 | H14: =IF(G14>0,1,0) -> 0 | I14: 1 | J14: 0 | K14: 101 | L14: 53 | M14: =MIN(L14/50,1) -> 1 | N14: 3 | O14: =SUM(N14/3)*2 -> 2 | P14: 1 | Q14: 1 | R14: 10 | S14: =SUM(F14,H14,J14,M14,O14,P14,Q14) -> 5 | T14: =IFERROR(S14/10,0) -> 0.5 | U14: =S14-10 -> -5 | V14: =IF(T14>=1,"Achieved",IF(T14>=0.7,"Near Target",IF(T14>=0.5,"Average","Low Performance"))) -> Average
A15: 46298 | B15: Jakir Ahammed Noor | C15: Batch-1 | D15: OCDL SO | E15: 0 | F15: =IF(E15>0,3,0) -> 0 | G15: 0 | H15: =IF(G15>0,1,0) -> 0 | I15: 1 | J15: =IF(I15>0,1,0) -> 1 | K15: 61 | L15: 52 | M15: =MIN(L15/50,1) -> 1 | N15: 3 | O15: =SUM(N15/3)*2 -> 2 | P15: 1 | Q15: 1 | R15: 10 | S15: =SUM(F15,H15,J15,M15,O15,P15,Q15) -> 6 | T15: =IFERROR(S15/10,0) -> 0.6 | U15: =S15-10 -> -4 | V15: =IF(T15>=1,"Achieved",IF(T15>=0.7,"Near Target",IF(T15>=0.5,"Average","Low Performance"))) -> Average
A16: 46298 | B16: Anowar Hossain | C16: Batch-1 | D16: OCDL SO | E16: 0 | F16: =IF(E16>0,3,0) -> 0 | G16: 0 | H16: =IF(G16>0,1,0) -> 0 | I16: 1 | J16: 0 | K16: 68 | L16: 58 | M16: =MIN(L16/50,1) -> 1 | N16: 3 | O16: =SUM(N16/3)*2 -> 2 | P16: 1 | Q16: 1 | R16: 10 | S16: =SUM(F16,H16,J16,M16,O16,P16,Q16) -> 5 | T16: =IFERROR(S16/10,0) -> 0.5 | U16: =S16-10 -> -5 | V16: =IF(T16>=1,"Achieved",IF(T16>=0.7,"Near Target",IF(T16>=0.5,"Average","Low Performance"))) -> Average
A17: 46298 | B17: Abrarul Haque Emon | C17: Batch-1 | D17: OCDL SO | E17: 0 | F17: =IF(E17>0,3,0) -> 0 | G17: 1 | H17: =IF(G17>0,1,0) -> 1 | I17: 1 | J17: =IF(I17>0,1,0) -> 1 | K17: 70 | L17: 54 | M17: =MIN(L17/50,1) -> 1 | N17: 3 | O17: =SUM(N17/3)*2 -> 2 | P17: 1 | Q17: 1 | R17: 10 | S17: =SUM(F17,H17,J17,M17,O17,P17,Q17) -> 7 | T17: =IFERROR(S17/10,0) -> 0.7 | U17: =S17-10 -> -3 | V17: =IF(T17>=1,"Achieved",IF(T17>=0.7,"Near Target",IF(T17>=0.5,"Average","Low Performance"))) -> Near Target
A18: 46298 | B18: Mst Sharmin Akter Nabila | C18: Batch-2 | D18: OCDL SO | E18: 0 | F18: =IF(E18>0,3,0) -> 0 | G18: 0 | H18: =IF(G18>0,1,0) -> 0 | I18: 0 | J18: =IF(I18>0,1,0) -> 0 | K18: 0 | L18: 0 | M18: =MIN(L18/50,1) -> 0 | O18: =SUM(N18/3)*2 -> 0 | P18: 0 | Q18: 0 | R18: 10 | S18: =SUM(F18,H18,J18,M18,O18,P18,Q18) -> 0 | T18: =IFERROR(S18/10,0) -> 0 | U18: =S18-10 -> -10 | V18: =IF(T18>=1,"Achieved",IF(T18>=0.7,"Near Target",IF(T18>=0.5,"Average","Low Performance"))) -> Low Performance | W18: Leave
A19: 46298 | B19: Afroza Yeasmin Rumi | C19: Batch-2 | D19: OCDL SO | E19: 0 | F19: =IF(E19>0,3,0) -> 0 | G19: 0 | H19: =IF(G19>0,1,0) -> 0 | I19: 1 | J19: =IF(I19>0,1,0) -> 1 | K19: 90 | L19: 58 | M19: =MIN(L19/50,1) -> 1 | N19: 3 | O19: =SUM(N19/3)*2 -> 2 | P19: 1 | Q19: 1 | R19: 10 | S19: =SUM(F19,H19,J19,M19,O19,P19,Q19) -> 6 | T19: =IFERROR(S19/10,0) -> 0.6 | U19: =S19-10 -> -4 | V19: =IF(T19>=1,"Achieved",IF(T19>=0.7,"Near Target",IF(T19>=0.5,"Average","Low Performance"))) -> Average
A20: 46298 | B20: Maria Akter Mim | C20: Batch-2 | D20: OCDL SO | E20: 0 | F20: =IF(E20>0,3,0) -> 0 | G20: 0 | H20: =IF(G20>0,1,0) -> 0 | I20: 1 | J20: =IF(I20>0,1,0) -> 1 | K20: 67 | L20: 52 | M20: =MIN(L20/50,1) -> 1 | N20: 3 | O20: =SUM(N20/3)*2 -> 2 | P20: 1 | Q20: 1 | R20: 10 | S20: =SUM(F20,H20,J20,M20,O20,P20,Q20) -> 6 | T20: =IFERROR(S20/10,0) -> 0.6 | U20: =S20-10 -> -4 | V20: =IF(T20>=1,"Achieved",IF(T20>=0.7,"Near Target",IF(T20>=0.5,"Average","Low Performance"))) -> Average
A21: 46298 | B21: Jahid Hasan E | C21: Batch-2 | D21: OCDL SO | E21: 0 | F21: =IF(E21>0,3,0) -> 0 | G21: 0 | H21: =IF(G21>0,1,0) -> 0 | I21: 1 | J21: 0 | K21: 67 | L21: 50 | M21: =MIN(L21/50,1) -> 1 | N21: 3 | O21: =SUM(N21/3)*2 -> 2 | P21: 1 | Q21: 1 | R21: 10 | S21: =SUM(F21,H21,J21,M21,O21,P21,Q21) -> 5 | T21: =IFERROR(S21/10,0) -> 0.5 | U21: =S21-10 -> -5 | V21: =IF(T21>=1,"Achieved",IF(T21>=0.7,"Near Target",IF(T21>=0.5,"Average","Low Performance"))) -> Average
A22: 46298 | B22: Safiqul Islam | C22: Batch-Ind | D22: OCDL SO | E22: 0 | F22: =IF(E22>0,3,0) -> 0 | G22: 0 | H22: =IF(G22>0,1,0) -> 0 | I22: 1 | J22: =IF(I22>0,1,0) -> 1 | K22: 62 | L22: 50 | M22: =MIN(L22/50,1) -> 1 | N22: 3 | O22: =SUM(N22/3)*2 -> 2 | P22: 1 | Q22: 1 | R22: 10 | S22: =SUM(F22,H22,J22,M22,O22,P22,Q22) -> 6 | T22: =IFERROR(S22/10,0) -> 0.6 | U22: =S22-10 -> -4 | V22: =IF(T22>=1,"Achieved",IF(T22>=0.7,"Near Target",IF(T22>=0.5,"Average","Low Performance"))) -> Average
A23: 46298 | B23: Manir Sikder | C23: Batch-Ind | D23: OCDL SO | E23: 0 | F23: =IF(E23>0,3,0) -> 0 | G23: 0 | H23: =IF(G23>0,1,0) -> 0 | I23: 1 | J23: =IF(I23>0,1,0) -> 1 | K23: 60 | L23: 50 | M23: =MIN(L23/50,1) -> 1 | N23: 3 | O23: =SUM(N23/3)*2 -> 2 | P23: 1 | Q23: 1 | R23: 10 | S23: =SUM(F23,H23,J23,M23,O23,P23,Q23) -> 6 | T23: =IFERROR(S23/10,0) -> 0.6 | U23: =S23-10 -> -4 | V23: =IF(T23>=1,"Achieved",IF(T23>=0.7,"Near Target",IF(T23>=0.5,"Average","Low Performance"))) -> Average
A24: 46298 | B24: Yeasin Rasel | C24: Batch-Ind | D24: OCDL SO | E24: 100000 | F24: =IF(E24>0,3,0) -> 3 | G24: 0 | H24: =IF(G24>0,1,0) -> 0 | I24: 1 | J24: =IF(I24>0,1,0) -> 1 | K24: 62 | L24: 52 | M24: =MIN(L24/50,1) -> 1 | N24: 3 | O24: =SUM(N24/3)*2 -> 2 | P24: 1 | Q24: 1 | R24: 10 | S24: =SUM(F24,H24,J24,M24,O24,P24,Q24) -> 9 | T24: =IFERROR(S24/10,0) -> 0.9 | U24: =S24-10 -> -1 | V24: =IF(T24>=1,"Achieved",IF(T24>=0.7,"Near Target",IF(T24>=0.5,"Average","Low Performance"))) -> Near Target
A25: 46299 | B25: Most. Liza Akter | C25: Batch-1 | D25: OCDL SO | E25: 0 | F25: =IF(E25>0,3,0) -> 0 | G25: 0 | H25: =IF(G25>0,1,0) -> 0 | I25: 1 | J25: =IF(I25>0,1,0) -> 1 | K25: 96 | L25: 50 | M25: =MIN(L25/50,1) -> 1 | N25: 3 | O25: =SUM(N25/3)*2 -> 2 | P25: 1 | Q25: 1 | R25: 10 | S25: =SUM(F25,H25,J25,M25,O25,P25,Q25) -> 6 | T25: =IFERROR(S25/10,0) -> 0.6 | U25: =S25-10 -> -4 | V25: =IF(T25>=1,"Achieved",IF(T25>=0.7,"Near Target",IF(T25>=0.5,"Average","Low Performance"))) -> Average
A26: 46299 | B26: Jakir Ahammed Noor | C26: Batch-1 | D26: OCDL SO | E26: 0 | F26: =IF(E26>0,3,0) -> 0 | G26: 0 | H26: =IF(G26>0,1,0) -> 0 | I26: 2 | J26: =IF(I26>0,1,0) -> 1 | K26: 65 | L26: 53 | M26: =MIN(L26/50,1) -> 1 | N26: 3 | O26: =SUM(N26/3)*2 -> 2 | P26: 1 | Q26: 1 | R26: 10 | S26: =SUM(F26,H26,J26,M26,O26,P26,Q26) -> 6 | T26: =IFERROR(S26/10,0) -> 0.6 | U26: =S26-10 -> -4 | V26: =IF(T26>=1,"Achieved",IF(T26>=0.7,"Near Target",IF(T26>=0.5,"Average","Low Performance"))) -> Average
A27: 46299 | B27: Anowar Hossain | C27: Batch-1 | D27: OCDL SO | E27: 0 | F27: =IF(E27>0,3,0) -> 0 | G27: 0 | H27: =IF(G27>0,1,0) -> 0 | I27: 2 | J27: =IF(I27>0,1,0) -> 1 | K27: 70 | L27: 55 | M27: =MIN(L27/50,1) -> 1 | N27: 3 | O27: =SUM(N27/3)*2 -> 2 | P27: 1 | Q27: 1 | R27: 10 | S27: =SUM(F27,H27,J27,M27,O27,P27,Q27) -> 6 | T27: =IFERROR(S27/10,0) -> 0.6 | U27: =S27-10 -> -4 | V27: =IF(T27>=1,"Achieved",IF(T27>=0.7,"Near Target",IF(T27>=0.5,"Average","Low Performance"))) -> Average
A28: 46299 | B28: Abrarul Haque Emon | C28: Batch-1 | D28: OCDL SO | E28: 0 | F28: =IF(E28>0,3,0) -> 0 | G28: 0 | H28: =IF(G28>0,1,0) -> 0 | I28: 3 | J28: =IF(I28>0,1,0) -> 1 | K28: 62 | L28: 51 | M28: =MIN(L28/50,1) -> 1 | N28: 3 | O28: =SUM(N28/3)*2 -> 2 | P28: 1 | Q28: 1 | R28: 10 | S28: =SUM(F28,H28,J28,M28,O28,P28,Q28) -> 6 | T28: =IFERROR(S28/10,0) -> 0.6 | U28: =S28-10 -> -4 | V28: =IF(T28>=1,"Achieved",IF(T28>=0.7,"Near Target",IF(T28>=0.5,"Average","Low Performance"))) -> Average
A29: 46299 | B29: Mst Sharmin Akter Nabila | C29: Batch-2 | D29: OCDL SO | E29: 0 | F29: =IF(E29>0,3,0) -> 0 | G29: 0 | H29: =IF(G29>0,1,0) -> 0 | I29: 0 | J29: =IF(I29>0,1,0) -> 0 | K29: 0 | L29: 0 | M29: =MIN(L29/50,1) -> 0 | O29: =SUM(N29/3)*2 -> 0 | P29: 0 | Q29: 0 | R29: 10 | S29: =SUM(F29,H29,J29,M29,O29,P29,Q29) -> 0 | T29: =IFERROR(S29/10,0) -> 0 | U29: =S29-10 -> -10 | V29: =IF(T29>=1,"Achieved",IF(T29>=0.7,"Near Target",IF(T29>=0.5,"Average","Low Performance"))) -> Low Performance | W29: Leave
A30: 46299 | B30: Afroza Yeasmin Rumi | C30: Batch-2 | D30: OCDL SO | E30: 0 | F30: =IF(E30>0,3,0) -> 0 | G30: 0 | H30: =IF(G30>0,1,0) -> 0 | I30: 1 | J30: =IF(I30>0,1,0) -> 1 | K30: 92 | L30: 54 | M30: =MIN(L30/50,1) -> 1 | N30: 3 | O30: =SUM(N30/3)*2 -> 2 | P30: 1 | Q30: 1 | R30: 10 | S30: =SUM(F30,H30,J30,M30,O30,P30,Q30) -> 6 | T30: =IFERROR(S30/10,0) -> 0.6 | U30: =S30-10 -> -4 | V30: =IF(T30>=1,"Achieved",IF(T30>=0.7,"Near Target",IF(T30>=0.5,"Average","Low Performance"))) -> Average
A31: 46299 | B31: Maria Akter Mim | C31: Batch-2 | D31: OCDL SO | E31: 0 | F31: =IF(E31>0,3,0) -> 0 | G31: 1 | H31: =IF(G31>0,1,0) -> 1 | I31: 0 | J31: =IF(I31>0,1,0) -> 0 | K31: 62 | L31: 53 | M31: =MIN(L31/50,1) -> 1 | N31: 3 | O31: =SUM(N31/3)*2 -> 2 | P31: 1 | Q31: 1 | R31: 10 | S31: =SUM(F31,H31,J31,M31,O31,P31,Q31) -> 6 | T31: =IFERROR(S31/10,0) -> 0.6 | U31: =S31-10 -> -4 | V31: =IF(T31>=1,"Achieved",IF(T31>=0.7,"Near Target",IF(T31>=0.5,"Average","Low Performance"))) -> Average
A32: 46299 | B32: Jahid Hasan E | C32: Batch-2 | D32: OCDL SO | E32: 0 | F32: =IF(E32>0,3,0) -> 0 | G32: 0 | H32: =IF(G32>0,1,0) -> 0 | I32: 1 | J32: =IF(I32>0,1,0) -> 1 | K32: 70 | L32: 51 | M32: =MIN(L32/50,1) -> 1 | N32: 3 | O32: =SUM(N32/3)*2 -> 2 | P32: 1 | Q32: 1 | R32: 10 | S32: =SUM(F32,H32,J32,M32,O32,P32,Q32) -> 6 | T32: =IFERROR(S32/10,0) -> 0.6 | U32: =S32-10 -> -4 | V32: =IF(T32>=1,"Achieved",IF(T32>=0.7,"Near Target",IF(T32>=0.5,"Average","Low Performance"))) -> Average
A33: 46299 | B33: Safiqul Islam | C33: Batch-Ind | D33: OCDL SO | E33: 0 | F33: =IF(E33>0,3,0) -> 0 | G33: 0 | H33: =IF(G33>0,1,0) -> 0 | I33: 2 | J33: =IF(I33>0,1,0) -> 1 | K33: 65 | L33: 52 | M33: =MIN(L33/50,1) -> 1 | N33: 3 | O33: =SUM(N33/3)*2 -> 2 | P33: 1 | Q33: 1 | R33: 10 | S33: =SUM(F33,H33,J33,M33,O33,P33,Q33) -> 6 | T33: =IFERROR(S33/10,0) -> 0.6 | U33: =S33-10 -> -4 | V33: =IF(T33>=1,"Achieved",IF(T33>=0.7,"Near Target",IF(T33>=0.5,"Average","Low Performance"))) -> Average
A34: 46299 | B34: Manir Sikder | C34: Batch-Ind | D34: OCDL SO | E34: 0 | F34: =IF(E34>0,3,0) -> 0 | G34: 0 | H34: =IF(G34>0,1,0) -> 0 | I34: 1 | J34: =IF(I34>0,1,0) -> 1 | K34: 64 | L34: 50 | M34: =MIN(L34/50,1) -> 1 | N34: 3 | O34: =SUM(N34/3)*2 -> 2 | P34: 1 | Q34: 1 | R34: 10 | S34: =SUM(F34,H34,J34,M34,O34,P34,Q34) -> 6 | T34: =IFERROR(S34/10,0) -> 0.6 | U34: =S34-10 -> -4 | V34: =IF(T34>=1,"Achieved",IF(T34>=0.7,"Near Target",IF(T34>=0.5,"Average","Low Performance"))) -> Average
A35: 46299 | B35: Yeasin Rasel | C35: Batch-Ind | D35: OCDL SO | E35: 0 | F35: =IF(E35>0,3,0) -> 0 | G35: 0 | H35: =IF(G35>0,1,0) -> 0 | I35: 1 | J35: =IF(I35>0,1,0) -> 1 | K35: 55 | L35: 50 | M35: =MIN(L35/50,1) -> 1 | N35: 3 | O35: =SUM(N35/3)*2 -> 2 | P35: 1 | Q35: 1 | R35: 10 | S35: =SUM(F35,H35,J35,M35,O35,P35,Q35) -> 6 | T35: =IFERROR(S35/10,0) -> 0.6 | U35: =S35-10 -> -4 | V35: =IF(T35>=1,"Achieved",IF(T35>=0.7,"Near Target",IF(T35>=0.5,"Average","Low Performance"))) -> Average
A36: 46300 | B36: Most. Liza Akter | C36: Batch-1 | D36: OCDL SO | E36: 0 | F36: =IF(E36>0,3,0) -> 0 | G36: 1 | H36: =IF(G36>0,1,0) -> 1 | I36: 1 | J36: =IF(I36>0,1,0) -> 1 | K36: 111 | L36: 55 | M36: =MIN(L36/50,1) -> 1 | N36: 3 | O36: =SUM(N36/3)*2 -> 2 | P36: 1 | Q36: 1 | R36: 10 | S36: =SUM(F36,H36,J36,M36,O36,P36,Q36) -> 7 | T36: =IFERROR(S36/10,0) -> 0.7 | U36: =S36-10 -> -3 | V36: =IF(T36>=1,"Achieved",IF(T36>=0.7,"Near Target",IF(T36>=0.5,"Average","Low Performance"))) -> Near Target
A37: 46300 | B37: Jakir Ahammed Noor | C37: Batch-1 | D37: OCDL SO | E37: 0 | F37: =IF(E37>0,3,0) -> 0 | G37: 1 | H37: =IF(G37>0,1,0) -> 1 | I37: 1 | J37: =IF(I37>0,1,0) -> 1 | K37: 69 | L37: 50 | M37: =MIN(L37/50,1) -> 1 | N37: 3 | O37: =SUM(N37/3)*2 -> 2 | P37: 1 | Q37: 1 | R37: 10 | S37: =SUM(F37,H37,J37,M37,O37,P37,Q37) -> 7 | T37: =IFERROR(S37/10,0) -> 0.7 | U37: =S37-10 -> -3 | V37: =IF(T37>=1,"Achieved",IF(T37>=0.7,"Near Target",IF(T37>=0.5,"Average","Low Performance"))) -> Near Target
A38: 46300 | B38: Anowar Hossain | C38: Batch-1 | D38: OCDL SO | E38: 0 | F38: =IF(E38>0,3,0) -> 0 | G38: 1 | H38: =IF(G38>0,1,0) -> 1 | I38: 1 | J38: =IF(I38>0,1,0) -> 1 | K38: 77 | L38: 52 | M38: =MIN(L38/50,1) -> 1 | N38: 3 | O38: =SUM(N38/3)*2 -> 2 | P38: 1 | Q38: 1 | R38: 10 | S38: =SUM(F38,H38,J38,M38,O38,P38,Q38) -> 7 | T38: =IFERROR(S38/10,0) -> 0.7 | U38: =S38-10 -> -3 | V38: =IF(T38>=1,"Achieved",IF(T38>=0.7,"Near Target",IF(T38>=0.5,"Average","Low Performance"))) -> Near Target
A39: 46300 | B39: Abrarul Haque Emon | C39: Batch-1 | D39: OCDL SO | E39: 0 | F39: =IF(E39>0,3,0) -> 0 | G39: 1 | H39: =IF(G39>0,1,0) -> 1 | I39: 1 | J39: =IF(I39>0,1,0) -> 1 | K39: 82 | L39: 52 | M39: =MIN(L39/50,1) -> 1 | N39: 3 | O39: =SUM(N39/3)*2 -> 2 | P39: 1 | Q39: 1 | R39: 10 | S39: =SUM(F39,H39,J39,M39,O39,P39,Q39) -> 7 | T39: =IFERROR(S39/10,0) -> 0.7 | U39: =S39-10 -> -3 | V39: =IF(T39>=1,"Achieved",IF(T39>=0.7,"Near Target",IF(T39>=0.5,"Average","Low Performance"))) -> Near Target
A40: 46300 | B40: Mahbubur Rahman | C40: Batch-1 | D40: OCDL SO | E40: 0 | F40: =IF(E40>0,3,0) -> 0 | G40: 0 | H40: =IF(G40>0,1,0) -> 0 | I40: 0 | J40: =IF(I40>0,1,0) -> 0 | K40: 0 | L40: 0 | M40: =MIN(L40/50,1) -> 0 | N40: 0 | O40: =SUM(N40/3)*2 -> 0 | P40: 1 | Q40: 1 | R40: 10 | S40: =SUM(F40,H40,J40,M40,O40,P40,Q40) -> 2 | T40: =IFERROR(S40/10,0) -> 0.2 | U40: =S40-10 -> -8 | V40: =IF(T40>=1,"Achieved",IF(T40>=0.7,"Near Target",IF(T40>=0.5,"Average","Low Performance"))) -> Low Performance
A41: 46300 | B41: Mst Sharmin Akter Nabila | C41: Batch-2 | D41: OCDL SO | E41: 0 | F41: =IF(E41>0,3,0) -> 0 | G41: 0 | H41: =IF(G41>0,1,0) -> 0 | I41: 1 | J41: =IF(I41>0,1,0) -> 1 | K41: 70 | L41: 51 | M41: =MIN(L41/50,1) -> 1 | N41: 3 | O41: =SUM(N41/3)*2 -> 2 | P41: 1 | Q41: 1 | R41: 10 | S41: =SUM(F41,H41,J41,M41,O41,P41,Q41) -> 6 | T41: =IFERROR(S41/10,0) -> 0.6 | U41: =S41-10 -> -4 | V41: =IF(T41>=1,"Achieved",IF(T41>=0.7,"Near Target",IF(T41>=0.5,"Average","Low Performance"))) -> Average
...

Sheet Working Process Daily KPI Entry
A2: Date | B2: Employee | C2: Batch | D2: Branch | E2: Collection Achv. | F2: Collection Point | G2: Int. Meeting Achv. | H2: Int. Meeting Point | I2: Ext. Meeting Achv | J2: Ext. Meeting Point | K2: Talk Time | L2: Client Reach/ Follow-up Achv. | M2: Client Reach/ Follow-up Point | N2: Appointment Achv. | O2: Appointment Point | P2: Dig. Marketing Point | Q2: Att. & Discipline Point | R2: KPI Mark Target | S2: Total KPI Points | T2: KPI Achievement % | U2: Gap | V2: Status | W2: Remarks
A3: 46296 | B3: Abu Sufian Shohag | C3: GM (Br. In Charge) | D3: OCDL SO | E3: 0
A4: 46296 | B4: Nurul Islam Ripon | C4: GM | D4: OCDL SO | E4: 0
A5: 46296 | B5: Touhidul Islam | C5: Sr. AGM | D5: OCDL SO | E5: 0
A6: 46296 | B6: Masud Shahriar | C6: AGM | D6: OCDL SO | E6: 300000 | F6: =IF(E6>0,3,0) -> 3 | G6: 1 | H6: =IF(G6>0,1,0) -> 1 | I6: 1 | J6: 1 | K6: 85 | L6: 50 | M6: =MIN(L6/50,1) -> 1 | N6: 3 | O6: =SUM(N6/3)*2 -> 2 | P6: 1 | Q6: 1 | R6: 10 | S6: =SUM(F6,H6,J6,M6,O6,P6,Q6) -> 10 | T6: =IFERROR(S6/10,0) -> 1 | U6: =S6-10 -> 0 | V6: =IF(T6>=1,"Achieved",IF(T6>=0.7,"Near Target",IF(T6>=0.5,"Average","Low Performance"))) -> Achieved
A7: 46296 | B7: Most. Liza Akter | C7: Batch-1 | D7: OCDL SO | E7: 0 | F7: =IF(E7>0,3,0) -> 0 | G7: 0 | H7: =IF(G7>0,1,0) -> 0 | I7: 1 | J7: =IF(I7>0,1,0) -> 1 | K7: 121 | L7: 52 | M7: =MIN(L7/50,1) -> 1 | N7: 3 | O7: =SUM(N7/3)*2 -> 2 | P7: 1 | Q7: 1 | R7: 10 | S7: =SUM(F7,H7,J7,M7,O7,P7,Q7) -> 6 | T7: =IFERROR(S7/10,0) -> 0.6 | U7: =S7-10 -> -4 | V7: =IF(T7>=1,"Achieved",IF(T7>=0.7,"Near Target",IF(T7>=0.5,"Average","Low Performance"))) -> Average
A8: 46296 | B8: Jakir Ahammed Noor | C8: Batch-1 | D8: OCDL SO | E8: 650000 | F8: =IF(E8>0,3,0) -> 3 | G8: 1 | H8: =IF(G8>0,1,0) -> 1 | I8: 2 | J8: =IF(I8>0,1,0) -> 1 | K8: 66 | L8: 51 | M8: =MIN(L8/50,1) -> 1 | N8: 3 | O8: =SUM(N8/3)*2 -> 2 | P8: 1 | Q8: 1 | R8: 10 | S8: =SUM(F8,H8,J8,M8,O8,P8,Q8) -> 10 | T8: =IFERROR(S8/10,0) -> 1 | U8: =S8-10 -> 0 | V8: =IF(T8>=1,"Achieved",IF(T8>=0.7,"Near Target",IF(T8>=0.5,"Average","Low Performance"))) -> Achieved
A9: 46296 | B9: Anowar Hossain | C9: Batch-1 | D9: OCDL SO | E9: 0 | F9: =IF(E9>0,3,0) -> 0 | G9: 0 | H9: =IF(G9>0,1,0) -> 0 | I9: 1 | J9: 1 | K9: 66 | L9: 52 | M9: =MIN(L9/50,1) -> 1 | N9: 3 | O9: =SUM(N9/3)*2 -> 2 | P9: 1 | Q9: 1 | R9: 10 | S9: =SUM(F9,H9,J9,M9,O9,P9,Q9) -> 6 | T9: =IFERROR(S9/10,0) -> 0.6 | U9: =S9-10 -> -4 | V9: =IF(T9>=1,"Achieved",IF(T9>=0.7,"Near Target",IF(T9>=0.5,"Average","Low Performance"))) -> Average
A10: 46296 | B10: Abrarul Haque Emon | C10: Batch-1 | D10: OCDL SO | E10: 300000 | F10: =IF(E10>0,3,0) -> 3 | G10: 1 | H10: =IF(G10>0,1,0) -> 1 | I10: 1 | J10: 1 | K10: 85 | L10: 50 | M10: =MIN(L10/50,1) -> 1 | N10: 3 | O10: =SUM(N10/3)*2 -> 2 | P10: 1 | Q10: 1 | R10: 10 | S10: =SUM(F10,H10,J10,M10,O10,P10,Q10) -> 10 | T10: =IFERROR(S10/10,0) -> 1 | U10: =S10-10 -> 0 | V10: =IF(T10>=1,"Achieved",IF(T10>=0.7,"Near Target",IF(T10>=0.5,"Average","Low Performance"))) -> Achieved
A11: 46296 | B11: Mst Sharmin Akter Nabila | C11: Batch-2 | D11: OCDL SO | E11: 0 | F11: =IF(E11>0,3,0) -> 0 | G11: 1 | H11: =IF(G11>0,1,0) -> 1 | I11: 0 | J11: 0 | K11: 80 | L11: 67 | M11: =MIN(L11/50,1) -> 1 | N11: 3 | O11: =SUM(N11/3)*2 -> 2 | P11: 1 | Q11: 1 | R11: 10 | S11: =SUM(F11,H11,J11,M11,O11,P11,Q11) -> 6 | T11: =IFERROR(S11/10,0) -> 0.6 | U11: =S11-10 -> -4 | V11: =IF(T11>=1,"Achieved",IF(T11>=0.7,"Near Target",IF(T11>=0.5,"Average","Low Performance"))) -> Average
A12: 46296 | B12: Afroza Yeasmin Rumi | C12: Batch-2 | D12: OCDL SO | E12: 0 | F12: =IF(E12>0,3,0) -> 0 | G12: 0 | H12: =IF(G12>0,1,0) -> 0 | I12: 1 | J12: =IF(I12>0,1,0) -> 1 | K12: 75 | L12: 53 | M12: =MIN(L12/50,1) -> 1 | N12: 3 | O12: =SUM(N12/3)*2 -> 2 | P12: 1 | Q12: 1 | R12: 10 | S12: =SUM(F12,H12,J12,M12,O12,P12,Q12) -> 6 | T12: =IFERROR(S12/10,0) -> 0.6 | U12: =S12-10 -> -4 | V12: =IF(T12>=1,"Achieved",IF(T12>=0.7,"Near Target",IF(T12>=0.5,"Average","Low Performance"))) -> Average
A13: 46296 | B13: Maria Akter Mim | C13: Batch-2 | D13: OCDL SO | E13: 0 | F13: =IF(E13>0,3,0) -> 0 | G13: 0 | H13: =IF(G13>0,1,0) -> 0 | I13: 1 | J13: 1 | K13: 64 | L13: 50 | M13: =MIN(L13/50,1) -> 1 | N13: 3 | O13: =SUM(N13/3)*2 -> 2 | P13: 1 | Q13: 1 | R13: 10 | S13: =SUM(F13,H13,J13,M13,O13,P13,Q13) -> 6 | T13: =IFERROR(S13/10,0) -> 0.6 | U13: =S13-10 -> -4 | V13: =IF(T13>=1,"Achieved",IF(T13>=0.7,"Near Target",IF(T13>=0.5,"Average","Low Performance"))) -> Average
A14: 46296 | B14: Jahid Hasan E | C14: Batch-2 | D14: OCDL SO | E14: 0 | F14: =IF(E14>0,3,0) -> 0 | G14: 0 | H14: =IF(G14>0,1,0) -> 0 | I14: 1 | J14: =IF(I14>0,1,0) -> 1 | K14: 65 | L14: 50 | M14: =MIN(L14/50,1) -> 1 | N14: 3 | O14: =SUM(N14/3)*2 -> 2 | P14: 1 | Q14: 1 | R14: 10 | S14: =SUM(F14,H14,J14,M14,O14,P14,Q14) -> 6 | T14: =IFERROR(S14/10,0) -> 0.6 | U14: =S14-10 -> -4 | V14: =IF(T14>=1,"Achieved",IF(T14>=0.7,"Near Target",IF(T14>=0.5,"Average","Low Performance"))) -> Average
A15: 46296 | B15: Safiqul Islam | C15: Batch-Ind | D15: OCDL SO | E15: 0 | F15: =IF(E15>0,3,0) -> 0 | G15: 0 | H15: =IF(G15>0,1,0) -> 0 | I15: 2 | J15: =IF(I15>0,1,0) -> 1 | K15: 75 | L15: 55 | M15: =MIN(L15/50,1) -> 1 | N15: 3 | O15: =SUM(N15/3)*2 -> 2 | P15: 1 | Q15: 1 | R15: 10 | S15: =SUM(F15,H15,J15,M15,O15,P15,Q15) -> 6 | T15: =IFERROR(S15/10,0) -> 0.6 | U15: =S15-10 -> -4 | V15: =IF(T15>=1,"Achieved",IF(T15>=0.7,"Near Target",IF(T15>=0.5,"Average","Low Performance"))) -> Average
A16: 46296 | B16: Manir Sikder | C16: Batch-Ind | D16: OCDL SO | E16: 0 | F16: =IF(E16>0,3,0) -> 0 | G16: 0 | H16: =IF(G16>0,1,0) -> 0 | I16: 2 | J16: =IF(I16>0,1,0) -> 1 | K16: 60 | L16: 50 | M16: =MIN(L16/50,1) -> 1 | N16: 3 | O16: =SUM(N16/3)*2 -> 2 | P16: 1 | Q16: 1 | R16: 10 | S16: =SUM(F16,H16,J16,M16,O16,P16,Q16) -> 6 | T16: =IFERROR(S16/10,0) -> 0.6 | U16: =S16-10 -> -4 | V16: =IF(T16>=1,"Achieved",IF(T16>=0.7,"Near Target",IF(T16>=0.5,"Average","Low Performance"))) -> Average
A17: 46296 | B17: Yeasin Rasel | C17: Batch-Ind | D17: OCDL SO | E17: 400000 | F17: =IF(E17>0,3,0) -> 3 | G17: 1 | H17: =IF(G17>0,1,0) -> 1 | I17: 1 | J17: =IF(I17>0,1,0) -> 1 | K17: 46 | L17: 50 | M17: =MIN(L17/50,1) -> 1 | N17: 3 | O17: =SUM(N17/3)*2 -> 2 | P17: 1 | Q17: 1 | R17: 10 | S17: =SUM(F17,H17,J17,M17,O17,P17,Q17) -> 10 | T17: =IFERROR(S17/10,0) -> 1 | U17: =S17-10 -> 0 | V17: =IF(T17>=1,"Achieved",IF(T17>=0.7,"Near Target",IF(T17>=0.5,"Average","Low Performance"))) -> Achieved
A18: 46298 | B18: Abu Sufian Shohag | C18: GM (Br. In Charge) | D18: OCDL SO | E18: 0 | F18: =IF(E18>0,3,0) -> 0 | G18: 0 | H18: =IF(G18>0,1,0) -> 0 | I18: 0 | J18: =IF(I18>0,1,0) -> 0 | K18: 0 | L18: 0 | M18: =MIN(L18/50,1) -> 0 | N18: 0 | O18: =SUM(N18/3)*2 -> 0 | P18: 0 | Q18: 0 | R18: 10 | S18: =SUM(F18,H18,J18,M18,O18,P18,Q18) -> 0 | T18: =IFERROR(S18/10,0) -> 0 | U18: =S18-10 -> -10 | V18: =IF(T18>=1,"Achieved",IF(T18>=0.7,"Near Target",IF(T18>=0.5,"Average","Low Performance"))) -> Low Performance
A19: 46298 | B19: Nurul Islam Ripon | C19: GM | D19: OCDL SO | E19: 0 | F19: =IF(E19>0,3,0) -> 0 | G19: 0 | H19: =IF(G19>0,1,0) -> 0 | I19: 0 | J19: =IF(I19>0,1,0) -> 0 | K19: 0 | L19: 0 | M19: =MIN(L19/50,1) -> 0 | N19: 0 | O19: =SUM(N19/3)*2 -> 0 | P19: 0 | Q19: 0 | R19: 10 | S19: =SUM(F19,H19,J19,M19,O19,P19,Q19) -> 0 | T19: =IFERROR(S19/10,0) -> 0 | U19: =S19-10 -> -10 | V19: =IF(T19>=1,"Achieved",IF(T19>=0.7,"Near Target",IF(T19>=0.5,"Average","Low Performance"))) -> Low Performance
A20: 46298 | B20: Touhidul Islam | C20: Sr. AGM | D20: OCDL SO | E20: 0 | F20: =IF(E20>0,3,0) -> 0 | G20: 0 | H20: =IF(G20>0,1,0) -> 0 | I20: 0 | J20: =IF(I20>0,1,0) -> 0 | K20: 0 | L20: 0 | M20: =MIN(L20/50,1) -> 0 | N20: 0 | O20: =SUM(N20/3)*2 -> 0 | P20: 0 | Q20: 0 | R20: 10 | S20: =SUM(F20,H20,J20,M20,O20,P20,Q20) -> 0 | T20: =IFERROR(S20/10,0) -> 0 | U20: =S20-10 -> -10 | V20: =IF(T20>=1,"Achieved",IF(T20>=0.7,"Near Target",IF(T20>=0.5,"Average","Low Performance"))) -> Low Performance
A21: 46298 | B21: Masud Shahriar | C21: AGM | D21: OCDL SO | E21: 0 | F21: =IF(E21>0,3,0) -> 0 | G21: 0 | H21: =IF(G21>0,1,0) -> 0 | I21: 0 | J21: =IF(I21>0,1,0) -> 0 | K21: 0 | L21: 0 | M21: =MIN(L21/50,1) -> 0 | N21: 0 | O21: =SUM(N21/3)*2 -> 0 | P21: 0 | Q21: 0 | R21: 10 | S21: =SUM(F21,H21,J21,M21,O21,P21,Q21) -> 0 | T21: =IFERROR(S21/10,0) -> 0 | U21: =S21-10 -> -10 | V21: =IF(T21>=1,"Achieved",IF(T21>=0.7,"Near Target",IF(T21>=0.5,"Average","Low Performance"))) -> Low Performance
A22: 46298 | B22: Most. Liza Akter | C22: Batch-1 | D22: OCDL SO | E22: 0 | F22: =IF(E22>0,3,0) -> 0 | G22: 0 | H22: =IF(G22>0,1,0) -> 0 | I22: 1 | J22: 0 | K22: 101 | L22: 53 | M22: =MIN(L22/50,1) -> 1 | N22: 3 | O22: =SUM(N22/3)*2 -> 2 | P22: 1 | Q22: 1 | R22: 10 | S22: =SUM(F22,H22,J22,M22,O22,P22,Q22) -> 5 | T22: =IFERROR(S22/10,0) -> 0.5 | U22: =S22-10 -> -5 | V22: =IF(T22>=1,"Achieved",IF(T22>=0.7,"Near Target",IF(T22>=0.5,"Average","Low Performance"))) -> Average
A23: 46298 | B23: Jakir Ahammed Noor | C23: Batch-1 | D23: OCDL SO | E23: 0 | F23: =IF(E23>0,3,0) -> 0 | G23: 0 | H23: =IF(G23>0,1,0) -> 0 | I23: 1 | J23: =IF(I23>0,1,0) -> 1 | K23: 61 | L23: 52 | M23: =MIN(L23/50,1) -> 1 | N23: 3 | O23: =SUM(N23/3)*2 -> 2 | P23: 1 | Q23: 1 | R23: 10 | S23: =SUM(F23,H23,J23,M23,O23,P23,Q23) -> 6 | T23: =IFERROR(S23/10,0) -> 0.6 | U23: =S23-10 -> -4 | V23: =IF(T23>=1,"Achieved",IF(T23>=0.7,"Near Target",IF(T23>=0.5,"Average","Low Performance"))) -> Average
A24: 46298 | B24: Anowar Hossain | C24: Batch-1 | D24: OCDL SO | E24: 0 | F24: =IF(E24>0,3,0) -> 0 | G24: 0 | H24: =IF(G24>0,1,0) -> 0 | I24: 1 | J24: 0 | K24: 68 | L24: 58 | M24: =MIN(L24/50,1) -> 1 | N24: 3 | O24: =SUM(N24/3)*2 -> 2 | P24: 1 | Q24: 1 | R24: 10 | S24: =SUM(F24,H24,J24,M24,O24,P24,Q24) -> 5 | T24: =IFERROR(S24/10,0) -> 0.5 | U24: =S24-10 -> -5 | V24: =IF(T24>=1,"Achieved",IF(T24>=0.7,"Near Target",IF(T24>=0.5,"Average","Low Performance"))) -> Average
A25: 46298 | B25: Abrarul Haque Emon | C25: Batch-1 | D25: OCDL SO | E25: 0 | F25: =IF(E25>0,3,0) -> 0 | G25: 1 | H25: =IF(G25>0,1,0) -> 1 | I25: 1 | J25: =IF(I25>0,1,0) -> 1 | K25: 70 | L25: 54 | M25: =MIN(L25/50,1) -> 1 | N25: 3 | O25: =SUM(N25/3)*2 -> 2 | P25: 1 | Q25: 1 | R25: 10 | S25: =SUM(F25,H25,J25,M25,O25,P25,Q25) -> 7 | T25: =IFERROR(S25/10,0) -> 0.7 | U25: =S25-10 -> -3 | V25: =IF(T25>=1,"Achieved",IF(T25>=0.7,"Near Target",IF(T25>=0.5,"Average","Low Performance"))) -> Near Target
A26: 46298 | B26: Mst Sharmin Akter Nabila | C26: Batch-2 | D26: OCDL SO | E26: 0 | F26: =IF(E26>0,3,0) -> 0 | G26: 0 | H26: =IF(G26>0,1,0) -> 0 | I26: 0 | J26: =IF(I26>0,1,0) -> 0 | K26: 0 | L26: 0 | M26: =MIN(L26/50,1) -> 0 | O26: =SUM(N26/3)*2 -> 0 | P26: 0 | Q26: 0 | R26: 10 | S26: =SUM(F26,H26,J26,M26,O26,P26,Q26) -> 0 | T26: =IFERROR(S26/10,0) -> 0 | U26: =S26-10 -> -10 | V26: =IF(T26>=1,"Achieved",IF(T26>=0.7,"Near Target",IF(T26>=0.5,"Average","Low Performance"))) -> Low Performance | W26: Leave
A27: 46298 | B27: Afroza Yeasmin Rumi | C27: Batch-2 | D27: OCDL SO | E27: 0 | F27: =IF(E27>0,3,0) -> 0 | G27: 0 | H27: =IF(G27>0,1,0) -> 0 | I27: 1 | J27: =IF(I27>0,1,0) -> 1 | K27: 90 | L27: 58 | M27: =MIN(L27/50,1) -> 1 | N27: 3 | O27: =SUM(N27/3)*2 -> 2 | P27: 1 | Q27: 1 | R27: 10 | S27: =SUM(F27,H27,J27,M27,O27,P27,Q27) -> 6 | T27: =IFERROR(S27/10,0) -> 0.6 | U27: =S27-10 -> -4 | V27: =IF(T27>=1,"Achieved",IF(T27>=0.7,"Near Target",IF(T27>=0.5,"Average","Low Performance"))) -> Average
A28: 46298 | B28: Maria Akter Mim | C28: Batch-2 | D28: OCDL SO | E28: 0 | F28: =IF(E28>0,3,0) -> 0 | G28: 0 | H28: =IF(G28>0,1,0) -> 0 | I28: 1 | J28: =IF(I28>0,1,0) -> 1 | K28: 67 | L28: 52 | M28: =MIN(L28/50,1) -> 1 | N28: 3 | O28: =SUM(N28/3)*2 -> 2 | P28: 1 | Q28: 1 | R28: 10 | S28: =SUM(F28,H28,J28,M28,O28,P28,Q28) -> 6 | T28: =IFERROR(S28/10,0) -> 0.6 | U28: =S28-10 -> -4 | V28: =IF(T28>=1,"Achieved",IF(T28>=0.7,"Near Target",IF(T28>=0.5,"Average","Low Performance"))) -> Average
A29: 46298 | B29: Jahid Hasan E | C29: Batch-2 | D29: OCDL SO | E29: 0 | F29: =IF(E29>0,3,0) -> 0 | G29: 0 | H29: =IF(G29>0,1,0) -> 0 | I29: 1 | J29: 0 | K29: 67 | L29: 50 | M29: =MIN(L29/50,1) -> 1 | N29: 3 | O29: =SUM(N29/3)*2 -> 2 | P29: 1 | Q29: 1 | R29: 10 | S29: =SUM(F29,H29,J29,M29,O29,P29,Q29) -> 5 | T29: =IFERROR(S29/10,0) -> 0.5 | U29: =S29-10 -> -5 | V29: =IF(T29>=1,"Achieved",IF(T29>=0.7,"Near Target",IF(T29>=0.5,"Average","Low Performance"))) -> Average
A30: 46298 | B30: Safiqul Islam | C30: Batch-Ind | D30: OCDL SO | E30: 0 | F30: =IF(E30>0,3,0) -> 0 | G30: 0 | H30: =IF(G30>0,1,0) -> 0 | I30: 1 | J30: =IF(I30>0,1,0) -> 1 | K30: 62 | L30: 50 | M30: =MIN(L30/50,1) -> 1 | N30: 3 | O30: =SUM(N30/3)*2 -> 2 | P30: 1 | Q30: 1 | R30: 10 | S30: =SUM(F30,H30,J30,M30,O30,P30,Q30) -> 6 | T30: =IFERROR(S30/10,0) -> 0.6 | U30: =S30-10 -> -4 | V30: =IF(T30>=1,"Achieved",IF(T30>=0.7,"Near Target",IF(T30>=0.5,"Average","Low Performance"))) -> Average
A31: 46298 | B31: Manir Sikder | C31: Batch-Ind | D31: OCDL SO | E31: 0 | F31: =IF(E31>0,3,0) -> 0 | G31: 0 | H31: =IF(G31>0,1,0) -> 0 | I31: 1 | J31: =IF(I31>0,1,0) -> 1 | K31: 60 | L31: 50 | M31: =MIN(L31/50,1) -> 1 | N31: 3 | O31: =SUM(N31/3)*2 -> 2 | P31: 1 | Q31: 1 | R31: 10 | S31: =SUM(F31,H31,J31,M31,O31,P31,Q31) -> 6 | T31: =IFERROR(S31/10,0) -> 0.6 | U31: =S31-10 -> -4 | V31: =IF(T31>=1,"Achieved",IF(T31>=0.7,"Near Target",IF(T31>=0.5,"Average","Low Performance"))) -> Average
A32: 46298 | B32: Yeasin Rasel | C32: Batch-Ind | D32: OCDL SO | E32: 100000 | F32: =IF(E32>0,3,0) -> 3 | G32: 0 | H32: =IF(G32>0,1,0) -> 0 | I32: 1 | J32: =IF(I32>0,1,0) -> 1 | K32: 62 | L32: 52 | M32: =MIN(L32/50,1) -> 1 | N32: 3 | O32: =SUM(N32/3)*2 -> 2 | P32: 1 | Q32: 1 | R32: 10 | S32: =SUM(F32,H32,J32,M32,O32,P32,Q32) -> 9 | T32: =IFERROR(S32/10,0) -> 0.9 | U32: =S32-10 -> -1 | V32: =IF(T32>=1,"Achieved",IF(T32>=0.7,"Near Target",IF(T32>=0.5,"Average","Low Performance"))) -> Near Target
A33: 46299 | B33: Abu Sufian Shohag | C33: GM (Br. In Charge) | D33: OCDL SO | E33: 0 | F33: =IF(E33>0,3,0) -> 0 | G33: 0 | H33: =IF(G33>0,1,0) -> 0 | I33: 0 | J33: =IF(I33>0,1,0) -> 0 | K33: 0 | L33: 0 | M33: =MIN(L33/50,1) -> 0 | N33: 0 | O33: =SUM(N33/3)*2 -> 0 | P33: 0 | Q33: 0 | R33: 10 | S33: =SUM(F33,H33,J33,M33,O33,P33,Q33) -> 0 | T33: =IFERROR(S33/10,0) -> 0 | U33: =S33-10 -> -10 | V33: =IF(T33>=1,"Achieved",IF(T33>=0.7,"Near Target",IF(T33>=0.5,"Average","Low Performance"))) -> Low Performance
A34: 46299 | B34: Nurul Islam Ripon | C34: GM | D34: OCDL SO | E34: 0 | F34: =IF(E34>0,3,0) -> 0 | G34: 0 | H34: =IF(G34>0,1,0) -> 0 | I34: 0 | J34: =IF(I34>0,1,0) -> 0 | K34: 0 | L34: 0 | M34: =MIN(L34/50,1) -> 0 | N34: 0 | O34: =SUM(N34/3)*2 -> 0 | P34: 0 | Q34: 0 | R34: 10 | S34: =SUM(F34,H34,J34,M34,O34,P34,Q34) -> 0 | T34: =IFERROR(S34/10,0) -> 0 | U34: =S34-10 -> -10 | V34: =IF(T34>=1,"Achieved",IF(T34>=0.7,"Near Target",IF(T34>=0.5,"Average","Low Performance"))) -> Low Performance
A35: 46299 | B35: Touhidul Islam | C35: Sr. AGM | D35: OCDL SO | E35: 0 | F35: =IF(E35>0,3,0) -> 0 | G35: 0 | H35: =IF(G35>0,1,0) -> 0 | I35: 0 | J35: =IF(I35>0,1,0) -> 0 | K35: 0 | L35: 0 | M35: =MIN(L35/50,1) -> 0 | N35: 0 | O35: =SUM(N35/3)*2 -> 0 | P35: 0 | Q35: 0 | R35: 10 | S35: =SUM(F35,H35,J35,M35,O35,P35,Q35) -> 0 | T35: =IFERROR(S35/10,0) -> 0 | U35: =S35-10 -> -10 | V35: =IF(T35>=1,"Achieved",IF(T35>=0.7,"Near Target",IF(T35>=0.5,"Average","Low Performance"))) -> Low Performance
A36: 46299 | B36: Masud Shahriar | C36: AGM | D36: OCDL SO | E36: 0 | F36: =IF(E36>0,3,0) -> 0 | G36: 0 | H36: =IF(G36>0,1,0) -> 0 | I36: 0 | J36: =IF(I36>0,1,0) -> 0 | K36: 0 | L36: 0 | M36: =MIN(L36/50,1) -> 0 | N36: 0 | O36: =SUM(N36/3)*2 -> 0 | P36: 0 | Q36: 0 | R36: 10 | S36: =SUM(F36,H36,J36,M36,O36,P36,Q36) -> 0 | T36: =IFERROR(S36/10,0) -> 0 | U36: =S36-10 -> -10 | V36: =IF(T36>=1,"Achieved",IF(T36>=0.7,"Near Target",IF(T36>=0.5,"Average","Low Performance"))) -> Low Performance
A37: 46299 | B37: Most. Liza Akter | C37: Batch-1 | D37: OCDL SO | E37: 0 | F37: =IF(E37>0,3,0) -> 0 | G37: 0 | H37: =IF(G37>0,1,0) -> 0 | I37: 0 | J37: =IF(I37>0,1,0) -> 0 | K37: 0 | L37: 0 | M37: =MIN(L37/50,1) -> 0 | N37: 0 | O37: =SUM(N37/3)*2 -> 0 | P37: 0 | Q37: 0 | R37: 10 | S37: =SUM(F37,H37,J37,M37,O37,P37,Q37) -> 0 | T37: =IFERROR(S37/10,0) -> 0 | U37: =S37-10 -> -10 | V37: =IF(T37>=1,"Achieved",IF(T37>=0.7,"Near Target",IF(T37>=0.5,"Average","Low Performance"))) -> Low Performance
A38: 46299 | B38: Jakir Ahammed Noor | C38: Batch-1 | D38: OCDL SO | E38: 0 | F38: =IF(E38>0,3,0) -> 0 | G38: 0 | H38: =IF(G38>0,1,0) -> 0 | I38: 0 | J38: =IF(I38>0,1,0) -> 0 | K38: 0 | L38: 0 | M38: =MIN(L38/50,1) -> 0 | N38: 0 | O38: =SUM(N38/3)*2 -> 0 | P38: 0 | Q38: 0 | R38: 10 | S38: =SUM(F38,H38,J38,M38,O38,P38,Q38) -> 0 | T38: =IFERROR(S38/10,0) -> 0 | U38: =S38-10 -> -10 | V38: =IF(T38>=1,"Achieved",IF(T38>=0.7,"Near Target",IF(T38>=0.5,"Average","Low Performance"))) -> Low Performance
A39: 46299 | B39: Anowar Hossain | C39: Batch-1 | D39: OCDL SO | E39: 0 | F39: =IF(E39>0,3,0) -> 0 | G39: 0 | H39: =IF(G39>0,1,0) -> 0 | I39: 0 | J39: =IF(I39>0,1,0) -> 0 | K39: 0 | L39: 0 | M39: =MIN(L39/50,1) -> 0 | N39: 0 | O39: =SUM(N39/3)*2 -> 0 | P39: 0 | Q39: 0 | R39: 10 | S39: =SUM(F39,H39,J39,M39,O39,P39,Q39) -> 0 | T39: =IFERROR(S39/10,0) -> 0 | U39: =S39-10 -> -10 | V39: =IF(T39>=1,"Achieved",IF(T39>=0.7,"Near Target",IF(T39>=0.5,"Average","Low Performance"))) -> Low Performance
A40: 46299 | B40: Abrarul Haque Emon | C40: Batch-1 | D40: OCDL SO | E40: 0 | F40: =IF(E40>0,3,0) -> 0 | G40: 0 | H40: =IF(G40>0,1,0) -> 0 | I40: 0 | J40: =IF(I40>0,1,0) -> 0 | K40: 0 | L40: 0 | M40: =MIN(L40/50,1) -> 0 | N40: 0 | O40: =SUM(N40/3)*2 -> 0 | P40: 0 | Q40: 0 | R40: 10 | S40: =SUM(F40,H40,J40,M40,O40,P40,Q40) -> 0 | T40: =IFERROR(S40/10,0) -> 0 | U40: =S40-10 -> -10 | V40: =IF(T40>=1,"Achieved",IF(T40>=0.7,"Near Target",IF(T40>=0.5,"Average","Low Performance"))) -> Low Performance
A41: 46299 | B41: Mst Sharmin Akter Nabila | C41: Batch-2 | D41: OCDL SO | E41: 0 | F41: =IF(E41>0,3,0) -> 0 | G41: 0 | H41: =IF(G41>0,1,0) -> 0 | I41: 0 | J41: =IF(I41>0,1,0) -> 0 | K41: 0 | L41: 0 | M41: =MIN(L41/50,1) -> 0 | N41: 0 | O41: =SUM(N41/3)*2 -> 0 | P41: 0 | Q41: 0 | R41: 10 | S41: =SUM(F41,H41,J41,M41,O41,P41,Q41) -> 0 | T41: =IFERROR(S41/10,0) -> 0 | U41: =S41-10 -> -10 | V41: =IF(T41>=1,"Achieved",IF(T41>=0.7,"Near Target",IF(T41>=0.5,"Average","Low Performance"))) -> Low Performance
...

Sheet Daily KPI Entry
A1: Daily KPI Dashboard — OCDL Sales Office : 06-October-2026
A2: Date | B2: Employee | C2: Batch | D2: Branch | E2: Collection Achv. | F2: Collection Point | G2: Int. Meeting Achv. | H2: Int. Meeting Point | I2: Ext. Meeting Achv | J2: Ext. Meeting Point | K2: Talk Time | L2: Client Reach/ Follow-up Achv. | M2: Client Reach/ Follow-up Point | N2: Appointment Achv. | O2: Appointment Point | P2: Dig. Marketing Point | Q2: Att. & Discipline Point | R2: KPI Mark Target | S2: Total KPI Points | T2: KPI Achievement % | U2: Gap | V2: Status | W2: Remarks
A3: 46301 | B3: Most. Liza Akter | C3: Batch-1 | D3: OCDL SO | E3: 50000 | F3: =IF(E3>0,3,0) -> 3 | G3: 1 | H3: =IF(G3>0,1,0) -> 1 | I3: 1 | J3: =IF(I3>0,1,0) -> 1 | K3: 108 | L3: 56 | M3: =MIN(L3/50,1) -> 1 | N3: 3 | O3: =SUM(N3/3)*2 -> 2 | P3: 1 | Q3: 1 | R3: 10 | S3: =SUM(F3,H3,J3,M3,O3,P3,Q3) -> 10 | T3: =IFERROR(S3/10,0) -> 1 | U3: =S3-10 -> 0 | V3: =IF(T3>=1,"Achieved",IF(T3>=0.7,"Near Target",IF(T3>=0.5,"Average","Low Performance"))) -> Achieved
A4: 46301 | B4: Jakir Ahammed Noor | C4: Batch-1 | D4: OCDL SO | E4: 0 | F4: =IF(E4>0,3,0) -> 0 | G4: 0 | H4: =IF(G4>0,1,0) -> 0 | I4: 1 | J4: =IF(I4>0,1,0) -> 1 | K4: 69 | L4: 55 | M4: =MIN(L4/50,1) -> 1 | N4: 3 | O4: =SUM(N4/3)*2 -> 2 | P4: 1 | Q4: 1 | R4: 10 | S4: =SUM(F4,H4,J4,M4,O4,P4,Q4) -> 6 | T4: =IFERROR(S4/10,0) -> 0.6 | U4: =S4-10 -> -4 | V4: =IF(T4>=1,"Achieved",IF(T4>=0.7,"Near Target",IF(T4>=0.5,"Average","Low Performance"))) -> Average
A5: 46301 | B5: Anowar Hossain | C5: Batch-1 | D5: OCDL SO | E5: 0 | F5: =IF(E5>0,3,0) -> 0 | G5: 1 | H5: =IF(G5>0,1,0) -> 1 | I5: 1 | J5: =IF(I5>0,1,0) -> 1 | K5: 65 | L5: 53 | M5: =MIN(L5/50,1) -> 1 | N5: 3 | O5: =SUM(N5/3)*2 -> 2 | P5: 1 | Q5: 1 | R5: 10 | S5: =SUM(F5,H5,J5,M5,O5,P5,Q5) -> 7 | T5: =IFERROR(S5/10,0) -> 0.7 | U5: =S5-10 -> -3 | V5: =IF(T5>=1,"Achieved",IF(T5>=0.7,"Near Target",IF(T5>=0.5,"Average","Low Performance"))) -> Near Target
A6: 46301 | B6: Abrarul Haque Emon | C6: Batch-1 | D6: OCDL SO | E6: 0 | F6: =IF(E6>0,3,0) -> 0 | G6: 0 | H6: =IF(G6>0,1,0) -> 0 | I6: 1 | J6: =IF(I6>0,1,0) -> 1 | K6: 79 | L6: 52 | M6: =MIN(L6/50,1) -> 1 | N6: 3 | O6: =SUM(N6/3)*2 -> 2 | P6: 1 | Q6: 1 | R6: 10 | S6: =SUM(F6,H6,J6,M6,O6,P6,Q6) -> 6 | T6: =IFERROR(S6/10,0) -> 0.6 | U6: =S6-10 -> -4 | V6: =IF(T6>=1,"Achieved",IF(T6>=0.7,"Near Target",IF(T6>=0.5,"Average","Low Performance"))) -> Average
A7: 46301 | B7: Mahbubur Rahman | C7: Batch-1 | D7: OCDL SO | E7: 0 | F7: =IF(E7>0,3,0) -> 0 | G7: 0 | H7: =IF(G7>0,1,0) -> 0 | I7: 0 | J7: =IF(I7>0,1,0) -> 0 | K7: 25 | L7: 20 | M7: =MIN(L7/50,1) -> 0.4 | N7: 0 | O7: =SUM(N7/3)*2 -> 0 | P7: 1 | Q7: 1 | R7: 10 | S7: =SUM(F7,H7,J7,M7,O7,P7,Q7) -> 2.4 | T7: =IFERROR(S7/10,0) -> 0.24 | U7: =S7-10 -> -7.6 | V7: =IF(T7>=1,"Achieved",IF(T7>=0.7,"Near Target",IF(T7>=0.5,"Average","Low Performance"))) -> Low Performance
A8: 46301 | B8: Mst Sharmin Akter Nabila | C8: Batch-2 | D8: OCDL SO | E8: 0 | F8: =IF(E8>0,3,0) -> 0 | G8: 0 | H8: =IF(G8>0,1,0) -> 0 | I8: 1 | J8: =IF(I8>0,1,0) -> 1 | K8: 80 | L8: 56 | M8: =MIN(L8/50,1) -> 1 | N8: 3 | O8: =SUM(N8/3)*2 -> 2 | P8: 1 | Q8: 1 | R8: 10 | S8: =SUM(F8,H8,J8,M8,O8,P8,Q8) -> 6 | T8: =IFERROR(S8/10,0) -> 0.6 | U8: =S8-10 -> -4 | V8: =IF(T8>=1,"Achieved",IF(T8>=0.7,"Near Target",IF(T8>=0.5,"Average","Low Performance"))) -> Average
A9: 46301 | B9: Afroza Yeasmin Rumi | C9: Batch-2 | D9: OCDL SO | E9: 0 | F9: =IF(E9>0,3,0) -> 0 | G9: 0 | H9: =IF(G9>0,1,0) -> 0 | I9: 1 | J9: =IF(I9>0,1,0) -> 1 | K9: 75 | L9: 51 | M9: =MIN(L9/50,1) -> 1 | N9: 3 | O9: =SUM(N9/3)*2 -> 2 | P9: 1 | Q9: 1 | R9: 10 | S9: =SUM(F9,H9,J9,M9,O9,P9,Q9) -> 6 | T9: =IFERROR(S9/10,0) -> 0.6 | U9: =S9-10 -> -4 | V9: =IF(T9>=1,"Achieved",IF(T9>=0.7,"Near Target",IF(T9>=0.5,"Average","Low Performance"))) -> Average
A10: 46301 | B10: Jahid Hasan E | C10: Batch-2 | D10: OCDL SO | E10: 0 | F10: =IF(E10>0,3,0) -> 0 | G10: 0 | H10: =IF(G10>0,1,0) -> 0 | I10: 1 | J10: =IF(I10>0,1,0) -> 1 | K10: 68 | L10: 52 | M10: =MIN(L10/50,1) -> 1 | N10: 3 | O10: =SUM(N10/3)*2 -> 2 | P10: 1 | Q10: 1 | R10: 10 | S10: =SUM(F10,H10,J10,M10,O10,P10,Q10) -> 6 | T10: =IFERROR(S10/10,0) -> 0.6 | U10: =S10-10 -> -4 | V10: =IF(T10>=1,"Achieved",IF(T10>=0.7,"Near Target",IF(T10>=0.5,"Average","Low Performance"))) -> Average
A11: 46301 | B11: Soniya Akter Putul | C11: Batch-2 | D11: OCDL SO | E11: 0 | F11: =IF(E11>0,3,0) -> 0 | G11: 0 | H11: =IF(G11>0,1,0) -> 0 | I11: 1 | J11: =IF(I11>0,1,0) -> 1 | K11: 20 | L11: 62 | M11: =MIN(L11/50,1) -> 1 | N11: 2 | O11: =SUM(N11/3)*2 -> 1.3333333 | P11: 1 | Q11: 1 | R11: 10 | S11: =SUM(F11,H11,J11,M11,O11,P11,Q11) -> 5.3333333 | T11: =IFERROR(S11/10,0) -> 0.53333333 | U11: =S11-10 -> -4.6666667 | V11: =IF(T11>=1,"Achieved",IF(T11>=0.7,"Near Target",IF(T11>=0.5,"Average","Low Performance"))) -> Average
A12: 46301 | B12: Maria Akter Mim | C12: Batch-2 | D12: OCDL SO | E12: 0 | F12: =IF(E12>0,3,0) -> 0 | G12: 0 | H12: =IF(G12>0,1,0) -> 0 | I12: 1 | J12: =IF(I12>0,1,0) -> 1 | K12: 62 | L12: 52 | M12: =MIN(L12/50,1) -> 1 | N12: 3 | O12: =SUM(N12/3)*2 -> 2 | P12: 1 | Q12: 1 | R12: 10 | S12: =SUM(F12,H12,J12,M12,O12,P12,Q12) -> 6 | T12: =IFERROR(S12/10,0) -> 0.6 | U12: =S12-10 -> -4 | V12: =IF(T12>=1,"Achieved",IF(T12>=0.7,"Near Target",IF(T12>=0.5,"Average","Low Performance"))) -> Average
A13: 46301 | B13: Safiqul Islam | C13: Batch-Ind | D13: OCDL SO | E13: 0 | F13: =IF(E13>0,3,0) -> 0 | G13: 0 | H13: =IF(G13>0,1,0) -> 0 | I13: 2 | J13: =IF(I13>0,1,0) -> 1 | K13: 65 | L13: 57 | M13: =MIN(L13/50,1) -> 1 | N13: 3 | O13: =SUM(N13/3)*2 -> 2 | P13: 1 | Q13: 1 | R13: 10 | S13: =SUM(F13,H13,J13,M13,O13,P13,Q13) -> 6 | T13: =IFERROR(S13/10,0) -> 0.6 | U13: =S13-10 -> -4 | V13: =IF(T13>=1,"Achieved",IF(T13>=0.7,"Near Target",IF(T13>=0.5,"Average","Low Performance"))) -> Average
A14: 46301 | B14: Manir Sikder | C14: Batch-Ind | D14: OCDL SO | E14: 0 | F14: =IF(E14>0,3,0) -> 0 | G14: 0 | H14: =IF(G14>0,1,0) -> 0 | I14: 2 | J14: =IF(I14>0,1,0) -> 1 | K14: 60 | L14: 50 | M14: =MIN(L14/50,1) -> 1 | N14: 3 | O14: =SUM(N14/3)*2 -> 2 | P14: 1 | Q14: 1 | R14: 10 | S14: =SUM(F14,H14,J14,M14,O14,P14,Q14) -> 6 | T14: =IFERROR(S14/10,0) -> 0.6 | U14: =S14-10 -> -4 | V14: =IF(T14>=1,"Achieved",IF(T14>=0.7,"Near Target",IF(T14>=0.5,"Average","Low Performance"))) -> Average
A15: 46301 | B15: Yeasin Rasel | C15: Batch-Ind | D15: OCDL SO | E15: 0 | F15: =IF(E15>0,3,0) -> 0 | G15: 0 | H15: =IF(G15>0,1,0) -> 0 | I15: 1 | J15: =IF(I15>0,1,0) -> 1 | K15: 0 | L15: 50 | M15: =MIN(L15/50,1) -> 1 | N15: 3 | O15: =SUM(N15/3)*2 -> 2 | P15: 1 | Q15: 1 | R15: 10 | S15: =SUM(F15,H15,J15,M15,O15,P15,Q15) -> 6 | T15: =IFERROR(S15/10,0) -> 0.6 | U15: =S15-10 -> -4 | V15: =IF(T15>=1,"Achieved",IF(T15>=0.7,"Near Target",IF(T15>=0.5,"Average","Low Performance"))) -> Average
D16: Tolat Average= | E16: =SUBTOTAL(109,E3:E15) -> 50000 | F16: =SUBTOTAL(109,F3:F15)/11 -> 0.27272727 | G16: =SUBTOTAL(109,G3:G15) -> 2 | H16: =SUBTOTAL(109,H3:H15)/13 -> 0.15384615 | I16: =SUBTOTAL(109,I3:I15) -> 14 | J16: =SUBTOTAL(109,J3:J15)/13 -> 0.92307692 | K16: =SUBTOTAL(109,K3:K15) -> 776 | L16: =SUBTOTAL(109,L3:L15) -> 666 | M16: =SUBTOTAL(109,M3:M15)/13 -> 0.95384615 | N16: =SUBTOTAL(109,N3:N15) -> 35 | O16: =SUBTOTAL(109,O3:O15)/13 -> 1.7948718 | P16: =SUBTOTAL(109,P3:P15)/13 -> 1 | Q16: =SUBTOTAL(109,Q3:Q15)/13 -> 1 | R16: =SUBTOTAL(109,R3:R15)/13 -> 10 | S16: ='Daily KPI Entry'!$F16+'Daily KPI Entry'!$H16+'Daily KPI Entry'!$J16+'Daily KPI Entry'!$M16+'Daily KPI Entry'!$O16+'Daily KPI Entry'!$P16+'Daily KPI Entry'!$Q16 -> 6.0983683 | T16: =SUBTOTAL(109,T3:T15)/13 -> 0.60564103 | U16: ='Daily KPI Entry'!$R16-'Daily KPI Entry'!$S16 -> 3.9016317 | V16: =IF(T16>=1,"Achieved",IF(T16>=0.7,"Near Target",IF(T16>=0.5,"Average","Low Performance"))) -> Average

Sheet Daily KPI Entry Sep26
A2: Date | B2: Employee | C2: Batch | D2: Branch | E2: Collection Achv. | F2: Collection Point | G2: Int. Meeting Achv. | H2: Int. Meeting Point | I2: Ext. Meeting Achv | J2: Ext. Meeting Point | K2: Talk Time | L2: Client Reach/ Follow-up Achv. | M2: Client Reach/ Follow-up Point | N2: Appointment Achv. | O2: Appointment Point | P2: Dig. Marketing Point | Q2: Att. & Discipline Point | R2: KPI Mark Target | S2: Total KPI Points | T2: KPI Achievement % | U2: Gap | V2: Status | W2: Remarks
A3: 46266 | B3: Most. Liza Akter | C3: Batch-1 | D3: OCDL SO | E3: 0 | F3: =IF(E3>0,3,0) -> 0 | G3: 0 | H3: =IF(G3>0,1,0) -> 0 | I3: 0 | J3: =IF(I3>0,1,0) -> 0 | K3: 107 | L3: 50 | M3: =MIN(L3/50,1) -> 1 | N3: 2 | O3: =SUM(N3/3)*2 -> 1.3333333 | P3: 1 | Q3: 1 | R3: 10 | S3: =SUM(F3,H3,J3,M3,O3,P3,Q3) -> 4.3333333 | T3: =IFERROR(S3/10,0) -> 0.43333333 | U3: =S3-10 -> -5.6666667 | V3: =IF(T3>=1,"Achieved",IF(T3>=0.7,"Near Target",IF(T3>=0.5,"Average","Low Performance"))) -> Low Performance
A4: 46266 | B4: Jakir Ahammed Noor | C4: Batch-1 | D4: OCDL SO | E4: 0 | F4: =IF(E4>0,3,0) -> 0 | G4: 0 | H4: =IF(G4>0,1,0) -> 0 | I4: 1 | J4: =IF(I4>0,1,0) -> 1 | K4: 66 | L4: 39 | M4: =MIN(L4/50,1) -> 0.78 | N4: 2 | O4: =SUM(N4/3)*2 -> 1.3333333 | P4: 1 | Q4: 0.75 | R4: 10 | S4: =SUM(F4,H4,J4,M4,O4,P4,Q4) -> 4.8633333 | T4: =IFERROR(S4/10,0) -> 0.48633333 | U4: =S4-10 -> -5.1366667 | V4: =IF(T4>=1,"Achieved",IF(T4>=0.7,"Near Target",IF(T4>=0.5,"Average","Low Performance"))) -> Low Performance
A5: 46266 | B5: Anowar Hossain | C5: Batch-1 | D5: OCDL SO | E5: 0 | F5: =IF(E5>0,3,0) -> 0 | G5: 0 | H5: =IF(G5>0,1,0) -> 0 | I5: 1 | J5: =IF(I5>0,1,0) -> 1 | K5: 74 | L5: 50 | M5: =MIN(L5/50,1) -> 1 | N5: 3 | O5: =SUM(N5/3)*2 -> 2 | P5: 1 | Q5: 0.75 | R5: 10 | S5: =SUM(F5,H5,J5,M5,O5,P5,Q5) -> 5.75 | T5: =IFERROR(S5/10,0) -> 0.575 | U5: =S5-10 -> -4.25 | V5: =IF(T5>=1,"Achieved",IF(T5>=0.7,"Near Target",IF(T5>=0.5,"Average","Low Performance"))) -> Average
A6: 46266 | B6: Abrarul Haque Emon | C6: Batch-1 | D6: OCDL SO | E6: 20000 | F6: =IF(E6>0,3,0) -> 3 | G6: 0 | H6: =IF(G6>0,1,0) -> 0 | I6: 1 | J6: =IF(I6>0,1,0) -> 1 | K6: 87 | L6: 40 | M6: =MIN(L6/50,1) -> 0.8 | N6: 2 | O6: =SUM(N6/3)*2 -> 1.3333333 | P6: 1 | Q6: 0.75 | R6: 10 | S6: =SUM(F6,H6,J6,M6,O6,P6,Q6) -> 7.8833333 | T6: =IFERROR(S6/10,0) -> 0.78833333 | U6: =S6-10 -> -2.1166667 | V6: =IF(T6>=1,"Achieved",IF(T6>=0.7,"Near Target",IF(T6>=0.5,"Average","Low Performance"))) -> Near Target
A7: 46266 | B7: Mst Sharmin Akter Nabila | C7: Batch-2 | D7: OCDL SO | E7: 0 | F7: =IF(E7>0,3,0) -> 0 | G7: 0 | H7: =IF(G7>0,1,0) -> 0 | I7: 0 | J7: =IF(I7>0,1,0) -> 0 | K7: 60 | L7: 41 | M7: =MIN(L7/50,1) -> 0.82 | N7: 1 | O7: =SUM(N7/3)*2 -> 0.66666667 | P7: 1 | Q7: 1 | R7: 10 | S7: =SUM(F7,H7,J7,M7,O7,P7,Q7) -> 3.4866667 | T7: =IFERROR(S7/10,0) -> 0.34866667 | U7: =S7-10 -> -6.5133333 | V7: =IF(T7>=1,"Achieved",IF(T7>=0.7,"Near Target",IF(T7>=0.5,"Average","Low Performance"))) -> Low Performance
A8: 46266 | B8: Afroza Yeasmin Rumi | C8: Batch-2 | D8: OCDL SO | E8: 0 | F8: =IF(E8>0,3,0) -> 0 | G8: 0 | H8: =IF(G8>0,1,0) -> 0 | I8: 0 | J8: =IF(I8>0,1,0) -> 0 | K8: 102 | L8: 26 | M8: =MIN(L8/50,1) -> 0.52 | N8: 1 | O8: =SUM(N8/3)*2 -> 0.66666667 | P8: 1 | Q8: 1 | R8: 10 | S8: =SUM(F8,H8,J8,M8,O8,P8,Q8) -> 3.1866667 | T8: =IFERROR(S8/10,0) -> 0.31866667 | U8: =S8-10 -> -6.8133333 | V8: =IF(T8>=1,"Achieved",IF(T8>=0.7,"Near Target",IF(T8>=0.5,"Average","Low Performance"))) -> Low Performance
A9: 46266 | B9: Maria Akter Mim | C9: Batch-2 | D9: OCDL SO | E9: 0 | F9: =IF(E9>0,3,0) -> 0 | G9: 0 | H9: =IF(G9>0,1,0) -> 0 | I9: 0 | J9: =IF(I9>0,1,0) -> 0 | K9: 62 | L9: 35 | M9: =MIN(L9/50,1) -> 0.7 | N9: 2 | O9: =SUM(N9/3)*2 -> 1.3333333 | P9: 1 | Q9: 1 | R9: 10 | S9: =SUM(F9,H9,J9,M9,O9,P9,Q9) -> 4.0333333 | T9: =IFERROR(S9/10,0) -> 0.40333333 | U9: =S9-10 -> -5.9666667 | V9: =IF(T9>=1,"Achieved",IF(T9>=0.7,"Near Target",IF(T9>=0.5,"Average","Low Performance"))) -> Low Performance
A10: 46266 | B10: Jahid Hasan E | C10: Batch-2 | D10: OCDL SO | E10: 0 | F10: =IF(E10>0,3,0) -> 0 | G10: 0 | H10: =IF(G10>0,1,0) -> 0 | I10: 0 | J10: =IF(I10>0,1,0) -> 0 | K10: 60 | L10: 50 | M10: =MIN(L10/50,1) -> 1 | N10: 2 | O10: =SUM(N10/3)*2 -> 1.3333333 | P10: 1 | Q10: 0.75 | R10: 10 | S10: =SUM(F10,H10,J10,M10,O10,P10,Q10) -> 4.0833333 | T10: =IFERROR(S10/10,0) -> 0.40833333 | U10: =S10-10 -> -5.9166667 | V10: =IF(T10>=1,"Achieved",IF(T10>=0.7,"Near Target",IF(T10>=0.5,"Average","Low Performance"))) -> Low Performance
A11: 46266 | B11: Omar Sharif Arman | C11: Batch-3 | D11: OCDL SO | E11: 0 | F11: =IF(E11>0,3,0) -> 0 | G11: 0 | H11: =IF(G11>0,1,0) -> 0 | I11: 0 | J11: =IF(I11>0,1,0) -> 0 | K11: 61 | L11: 38 | M11: =MIN(L11/50,1) -> 0.76 | N11: 1 | O11: =SUM(N11/3)*2 -> 0.66666667 | P11: 1 | Q11: 0.5 | R11: 10 | S11: =SUM(F11,H11,J11,M11,O11,P11,Q11) -> 2.9266667 | T11: =IFERROR(S11/10,0) -> 0.29266667 | U11: =S11-10 -> -7.0733333 | V11: =IF(T11>=1,"Achieved",IF(T11>=0.7,"Near Target",IF(T11>=0.5,"Average","Low Performance"))) -> Low Performance
A12: 46266 | B12: Safiqul Islam | C12: Batch-3 | D12: OCDL SO | E12: 0 | F12: =IF(E12>0,3,0) -> 0 | G12: 0 | H12: =IF(G12>0,1,0) -> 0 | I12: 1 | J12: =IF(I12>0,1,0) -> 1 | K12: 60 | L12: 40 | M12: =MIN(L12/50,1) -> 0.8 | N12: 2 | O12: =SUM(N12/3)*2 -> 1.3333333 | P12: 1 | Q12: 0.75 | R12: 10 | S12: =SUM(F12,H12,J12,M12,O12,P12,Q12) -> 4.8833333 | T12: =IFERROR(S12/10,0) -> 0.48833333 | U12: =S12-10 -> -5.1166667 | V12: =IF(T12>=1,"Achieved",IF(T12>=0.7,"Near Target",IF(T12>=0.5,"Average","Low Performance"))) -> Low Performance
A13: 46266 | B13: Manir Sikder | C13: Batch-3 | D13: OCDL SO | E13: 0 | F13: =IF(E13>0,3,0) -> 0 | G13: 0 | H13: =IF(G13>0,1,0) -> 0 | I13: 0 | J13: =IF(I13>0,1,0) -> 0 | K13: 0 | L13: 0 | M13: =MIN(L13/50,1) -> 0 | O13: =SUM(N13/3)*2 -> 0 | P13: 0 | Q13: 0 | R13: 10 | S13: =SUM(F13,H13,J13,M13,O13,P13,Q13) -> 0 | T13: =IFERROR(S13/10,0) -> 0 | U13: =S13-10 -> -10 | V13: =IF(T13>=1,"Achieved",IF(T13>=0.7,"Near Target",IF(T13>=0.5,"Average","Low Performance"))) -> Low Performance | W13: Leave
A14: 46266 | B14: Yeasin Rasel | C14: Batch-3 | D14: OCDL SO | E14: 0 | F14: =IF(E14>0,3,0) -> 0 | G14: 0 | H14: =IF(G14>0,1,0) -> 0 | I14: 0 | J14: =IF(I14>0,1,0) -> 0 | K14: 0 | L14: 0 | M14: =MIN(L14/50,1) -> 0 | O14: =SUM(N14/3)*2 -> 0 | P14: 0 | Q14: 0 | R14: 10 | S14: =SUM(F14,H14,J14,M14,O14,P14,Q14) -> 0 | T14: =IFERROR(S14/10,0) -> 0 | U14: =S14-10 -> -10 | V14: =IF(T14>=1,"Achieved",IF(T14>=0.7,"Near Target",IF(T14>=0.5,"Average","Low Performance"))) -> Low Performance | W14: visit
A15: 46267 | B15: Most. Liza Akter | C15: Batch-1 | D15: OCDL SO | E15: 0 | F15: =IF(E15>0,3,0) -> 0 | G15: 1 | H15: =IF(G15>0,1,0) -> 1 | I15: 0 | J15: =IF(I15>0,1,0) -> 0 | K15: 125 | L15: 50 | M15: =MIN(L15/50,1) -> 1 | N15: 2 | O15: =SUM(N15/3)*2 -> 1.3333333 | P15: 1 | Q15: 1 | R15: 10 | S15: =SUM(F15,H15,J15,M15,O15,P15,Q15) -> 5.3333333 | T15: =IFERROR(S15/10,0) -> 0.53333333 | U15: =S15-10 -> -4.6666667 | V15: =IF(T15>=1,"Achieved",IF(T15>=0.7,"Near Target",IF(T15>=0.5,"Average","Low Performance"))) -> Average
A16: 46267 | B16: Jakir Ahammed Noor | C16: Batch-1 | D16: OCDL SO | E16: 0 | F16: =IF(E16>0,3,0) -> 0 | G16: 0 | H16: =IF(G16>0,1,0) -> 0 | I16: 1 | J16: =IF(I16>0,1,0) -> 1 | K16: 63 | L16: 42 | M16: =MIN(L16/50,1) -> 0.84 | N16: 2 | O16: =SUM(N16/3)*2 -> 1.3333333 | P16: 1 | Q16: 0.75 | R16: 10 | S16: =SUM(F16,H16,J16,M16,O16,P16,Q16) -> 4.9233333 | T16: =IFERROR(S16/10,0) -> 0.49233333 | U16: =S16-10 -> -5.0766667 | V16: =IF(T16>=1,"Achieved",IF(T16>=0.7,"Near Target",IF(T16>=0.5,"Average","Low Performance"))) -> Low Performance
A17: 46267 | B17: Anowar Hossain | C17: Batch-1 | D17: OCDL SO | E17: 0 | F17: =IF(E17>0,3,0) -> 0 | G17: 0 | H17: =IF(G17>0,1,0) -> 0 | I17: 1 | J17: =IF(I17>0,1,0) -> 1 | K17: 69 | L17: 50 | M17: =MIN(L17/50,1) -> 1 | N17: 3 | O17: =SUM(N17/3)*2 -> 2 | P17: 1 | Q17: 0.75 | R17: 10 | S17: =SUM(F17,H17,J17,M17,O17,P17,Q17) -> 5.75 | T17: =IFERROR(S17/10,0) -> 0.575 | U17: =S17-10 -> -4.25 | V17: =IF(T17>=1,"Achieved",IF(T17>=0.7,"Near Target",IF(T17>=0.5,"Average","Low Performance"))) -> Average
A18: 46267 | B18: Abrarul Haque Emon | C18: Batch-1 | D18: OCDL SO | F18: =IF(E18>0,3,0) -> 0 | H18: =IF(G18>0,1,0) -> 0 | I18: 4 | J18: =IF(I18>0,1,0) -> 1 | K18: 66 | L18: 50 | M18: =MIN(L18/50,1) -> 1 | N18: 3 | O18: =SUM(N18/3)*2 -> 2 | P18: 1 | Q18: 0.75 | R18: 10 | S18: =SUM(F18,H18,J18,M18,O18,P18,Q18) -> 5.75 | T18: =IFERROR(S18/10,0) -> 0.575 | U18: =S18-10 -> -4.25 | V18: =IF(T18>=1,"Achieved",IF(T18>=0.7,"Near Target",IF(T18>=0.5,"Average","Low Performance"))) -> Average
A19: 46267 | B19: Mst Sharmin Akter Nabila | C19: Batch-2 | D19: OCDL SO | E19: 0 | F19: =IF(E19>0,3,0) -> 0 | G19: 0 | H19: =IF(G19>0,1,0) -> 0 | I19: 0 | J19: =IF(I19>0,1,0) -> 0 | L19: 50 | M19: =MIN(L19/50,1) -> 1 | N19: 2 | O19: =SUM(N19/3)*2 -> 1.3333333 | P19: 1 | Q19: 1 | R19: 10 | S19: =SUM(F19,H19,J19,M19,O19,P19,Q19) -> 4.3333333 | T19: =IFERROR(S19/10,0) -> 0.43333333 | U19: =S19-10 -> -5.6666667 | V19: =IF(T19>=1,"Achieved",IF(T19>=0.7,"Near Target",IF(T19>=0.5,"Average","Low Performance"))) -> Low Performance
A20: 46267 | B20: Afroza Yeasmin Rumi | C20: Batch-2 | D20: OCDL SO | E20: 0 | F20: =IF(E20>0,3,0) -> 0 | G20: 0 | H20: =IF(G20>0,1,0) -> 0 | I20: 1 | J20: =IF(I20>0,1,0) -> 1 | K20: 91 | L20: 31 | M20: =MIN(L20/50,1) -> 0.62 | N20: 2 | O20: =SUM(N20/3)*2 -> 1.3333333 | P20: 1 | Q20: 1 | R20: 10 | S20: =SUM(F20,H20,J20,M20,O20,P20,Q20) -> 4.9533333 | T20: =IFERROR(S20/10,0) -> 0.49533333 | U20: =S20-10 -> -5.0466667 | V20: =IF(T20>=1,"Achieved",IF(T20>=0.7,"Near Target",IF(T20>=0.5,"Average","Low Performance"))) -> Low Performance
A21: 46267 | B21: Maria Akter Mim | C21: Batch-2 | D21: OCDL SO | E21: 0 | F21: =IF(E21>0,3,0) -> 0 | G21: 0 | H21: =IF(G21>0,1,0) -> 0 | I21: 0 | J21: =IF(I21>0,1,0) -> 0 | K21: 69 | L21: 50 | M21: =MIN(L21/50,1) -> 1 | N21: 2 | O21: =SUM(N21/3)*2 -> 1.3333333 | P21: 1 | Q21: 1 | R21: 10 | S21: =SUM(F21,H21,J21,M21,O21,P21,Q21) -> 4.3333333 | T21: =IFERROR(S21/10,0) -> 0.43333333 | U21: =S21-10 -> -5.6666667 | V21: =IF(T21>=1,"Achieved",IF(T21>=0.7,"Near Target",IF(T21>=0.5,"Average","Low Performance"))) -> Low Performance
A22: 46267 | B22: Jahid Hasan E | C22: Batch-2 | D22: OCDL SO | E22: 0 | F22: =IF(E22>0,3,0) -> 0 | G22: 0 | H22: =IF(G22>0,1,0) -> 0 | I22: 0 | J22: 0 | K22: 65 | L22: 50 | M22: =MIN(L22/50,1) -> 1 | N22: 2 | O22: =SUM(N22/3)*2 -> 1.3333333 | P22: 1 | Q22: 0.75 | R22: 10 | S22: =SUM(F22,H22,J22,M22,O22,P22,Q22) -> 4.0833333 | T22: =IFERROR(S22/10,0) -> 0.40833333 | U22: =S22-10 -> -5.9166667 | V22: =IF(T22>=1,"Achieved",IF(T22>=0.7,"Near Target",IF(T22>=0.5,"Average","Low Performance"))) -> Low Performance
A23: 46267 | B23: Omar Sharif Arman | C23: Batch-3 | D23: OCDL SO | E23: 0 | F23: =IF(E23>0,3,0) -> 0 | G23: 0 | H23: =IF(G23>0,1,0) -> 0 | I23: 0 | J23: =IF(I23>0,1,0) -> 0 | K23: 27 | L23: 39 | M23: =MIN(L23/50,1) -> 0.78 | N23: 1 | O23: =SUM(N23/3)*2 -> 0.66666667 | P23: 1 | Q23: 0.75 | R23: 10 | S23: =SUM(F23,H23,J23,M23,O23,P23,Q23) -> 3.1966667 | T23: =IFERROR(S23/10,0) -> 0.31966667 | U23: =S23-10 -> -6.8033333 | V23: =IF(T23>=1,"Achieved",IF(T23>=0.7,"Near Target",IF(T23>=0.5,"Average","Low Performance"))) -> Low Performance
A24: 46267 | B24: Safiqul Islam | C24: Batch-3 | D24: OCDL SO | E24: 0 | F24: =IF(E24>0,3,0) -> 0 | G24: 0 | H24: =IF(G24>0,1,0) -> 0 | I24: 3 | J24: =IF(I24>0,1,0) -> 1 | K24: 35 | L24: 35 | M24: =MIN(L24/50,1) -> 0.7 | N24: 2 | O24: =SUM(N24/3)*2 -> 1.3333333 | P24: 1 | Q24: 0.75 | R24: 10 | S24: =SUM(F24,H24,J24,M24,O24,P24,Q24) -> 4.7833333 | T24: =IFERROR(S24/10,0) -> 0.47833333 | U24: =S24-10 -> -5.2166667 | V24: =IF(T24>=1,"Achieved",IF(T24>=0.7,"Near Target",IF(T24>=0.5,"Average","Low Performance"))) -> Low Performance
A25: 46267 | B25: Manir Sikder | C25: Batch-3 | D25: OCDL SO | E25: 0 | F25: =IF(E25>0,3,0) -> 0 | G25: 0 | H25: =IF(G25>0,1,0) -> 0 | I25: 0 | J25: =IF(I25>0,1,0) -> 0 | K25: 0 | L25: 0 | M25: =MIN(L25/50,1) -> 0 | O25: =SUM(N25/3)*2 -> 0 | P25: 0 | Q25: 0 | R25: 10 | S25: =SUM(F25,H25,J25,M25,O25,P25,Q25) -> 0 | T25: =IFERROR(S25/10,0) -> 0 | U25: =S25-10 -> -10 | V25: =IF(T25>=1,"Achieved",IF(T25>=0.7,"Near Target",IF(T25>=0.5,"Average","Low Performance"))) -> Low Performance | W25: Leave
A26: 46267 | B26: Yeasin Rasel | C26: Batch-3 | D26: OCDL SO | E26: 0 | F26: =IF(E26>0,3,0) -> 0 | G26: 0 | H26: =IF(G26>0,1,0) -> 0 | I26: 0 | J26: =IF(I26>0,1,0) -> 0 | K26: 44 | L26: 38 | M26: =MIN(L26/50,1) -> 0.76 | N26: 2 | O26: =SUM(N26/3)*2 -> 1.3333333 | P26: 1 | Q26: 0.75 | R26: 10 | S26: =SUM(F26,H26,J26,M26,O26,P26,Q26) -> 3.8433333 | T26: =IFERROR(S26/10,0) -> 0.38433333 | U26: =S26-10 -> -6.1566667 | V26: =IF(T26>=1,"Achieved",IF(T26>=0.7,"Near Target",IF(T26>=0.5,"Average","Low Performance"))) -> Low Performance
A27: 46268 | B27: Most. Liza Akter | C27: Batch-1 | D27: OCDL SO | E27: 0 | F27: =IF(E27>0,3,0) -> 0 | G27: 0 | H27: =IF(G27>0,1,0) -> 0 | I27: 0 | J27: =IF(I27>0,1,0) -> 0 | K27: 120 | L27: 50 | M27: =MIN(L27/50,1) -> 1 | N27: 2 | O27: =SUM(N27/3)*2 -> 1.3333333 | P27: 1 | Q27: 1 | R27: 10 | S27: =SUM(F27,H27,J27,M27,O27,P27,Q27) -> 4.3333333 | T27: =IFERROR(S27/10,0) -> 0.43333333 | U27: =S27-10 -> -5.6666667 | V27: =IF(T27>=1,"Achieved",IF(T27>=0.7,"Near Target",IF(T27>=0.5,"Average","Low Performance"))) -> Low Performance
A28: 46268 | B28: Jakir Ahammed Noor | C28: Batch-1 | D28: OCDL SO | E28: 0 | F28: =IF(E28>0,3,0) -> 0 | G28: 1 | H28: =IF(G28>0,1,0) -> 1 | I28: 1 | J28: =IF(I28>0,1,0) -> 1 | K28: 64 | L28: 47 | M28: =MIN(L28/50,1) -> 0.94 | N28: 2 | O28: =SUM(N28/3)*2 -> 1.3333333 | P28: 1 | Q28: 0.75 | R28: 10 | S28: =SUM(F28,H28,J28,M28,O28,P28,Q28) -> 6.0233333 | T28: =IFERROR(S28/10,0) -> 0.60233333 | U28: =S28-10 -> -3.9766667 | V28: =IF(T28>=1,"Achieved",IF(T28>=0.7,"Near Target",IF(T28>=0.5,"Average","Low Performance"))) -> Average
A29: 46268 | B29: Anowar Hossain | C29: Batch-1 | D29: OCDL SO | E29: 0 | F29: =IF(E29>0,3,0) -> 0 | G29: 0 | H29: =IF(G29>0,1,0) -> 0 | I29: 0 | J29: =IF(I29>0,1,0) -> 0 | K29: 0 | L29: 0 | M29: =MIN(L29/50,1) -> 0 | O29: =SUM(N29/3)*2 -> 0 | P29: 0 | Q29: 0 | R29: 10 | S29: =SUM(F29,H29,J29,M29,O29,P29,Q29) -> 0 | T29: =IFERROR(S29/10,0) -> 0 | U29: =S29-10 -> -10 | V29: =IF(T29>=1,"Achieved",IF(T29>=0.7,"Near Target",IF(T29>=0.5,"Average","Low Performance"))) -> Low Performance | W29: Leave
